Workbook

Sheet Page1
A1: MERCHANT | B1: INVOICE
A2: JAIKVIN GLOBAL | F2: Invoice No. | G2: JG/26-27/6002 DT 04.05.2026 | K2: Exporter's Ref.
F3: Date: | K3: IEC AVIPS4808H
A4: Merchant Exporters | F4: Buyers Order No: | H4: JG/26-P/09 DT 27.04.2026
A5: A-101, Rajshree Royale, Navroji Lane, Ghatkopar (W),
A6: MUMBAI-400 086. Maharashtra (State Code : 27) | F6: Other Reference(s):
A7: Tel: 9987122600 E-Mail: aalok.shah@jaikvinglobal.com
A8: On Account & Risks of: | F8: IRN No | G8: 5049ef43c7126a4c35bf29795ce49390de0338
A9: Messrs Corecomp Pty Ltd., | G9: c2897a4b4929c186580cfacad7
A10: T/A G.D.Watermark | F10: Ack No | G10: 122632432448548
A11: 13, Tesla Link,
A12: Wangara WA 6065 (Australia) | F12: Ack Dt | G12: 04-05-2026 3:51:00 PM
A13: Invoice of: | B13: PLASTIC (PP) EXTRUDED PIPES, PLASTIC (PP) | F13: Country of Origin | I13: Country of Final Destination
B14: & (PA) MOULDED FITTINGS AND CORRUGATED | F14: INDIA | I14: AUSTRALIA
B15: BOXES | F15: BL. NO. | G15: SFPM2605165498 DT. 19.05.2026
A16: Pre-Carraige by: | C16: Place of Receipt by Pre-Carraige | F16: Shipped Per | G16: CAPE SYROS VOYAGE 092E
F17: S/B No: | G17: 2945305 DT. 04.05.2026
A18: Shipped per: | C18: Port of Loading: | F18: Terms of Delivery: | H18: FOB MUMBAI
A19: =G16 -> CAPE SYROS VOYAGE 092E | C19: NHAVA SHEVA-MUMBAI (INDIA) | F19: Terms of Payment: | H19: D.P.SIGHT DRAFT
A20: Port of Discharge: | C20: Port of destination | F20: Through: | H20: HDFC BANK LTD, GHATKOPAR (E) BRANCH
A21: FREMANTLE | C21: FREMANTLE | H21: GHATKOPAR (E), MUMBAI 400 077 (INDIA)
A22: Marks & Nos. | B22: No & Kinds of Pkgs Description of Goods | E22: Quantity | F22: Rate | G22: Amount | H22: Rate | I22: Taxable Amount | J22: GST Rate | K22: GST Amount
A23: GDW NOS : | B23: 421 PACKAGES (343 CARTONS & 78 HDP BUNDLES) CONTAINING | F23: FOB MUMBAI IN US$ | H23: FOB MUMBAI IN INR
A24: 2001 - 2421 | B24: PLASTIC (PP) EXTRUDED PIPES, PLASTIC (PP) & | H24: EX. RATE @ Rs.92.50
A25: 2421 | B25: (PA) MOULDED FITTINGS & CORRUGATED BOXES
B26: PLASTIC (PP) EXTRUDED PIPES : BOTH SIDE THREADED PIPES (HSN CODE : 3917.2200)
B27: CODE | C27: SIZE (IN / MM) | D27: LEN (MM) | E27: PIECES | F27: PER PC
B28: PP1509 | C28: 15 | D28: 225 | E28: 6000 | F28: 0.07 | G28: =E28*F28 -> 420 | H28: =I28/E28 -> 6.475 | I28: 38850 | J28: 0.18 | K28: =ROUND(I28*J28,) -> 6993
B29: PP1518 | C29: 15 | D29: 457 | E29: 7200 | F29: 0.24 | G29: =E29*F29 -> 1728 | H29: =I29/E29 -> 22.2 | I29: 159840 | J29: 0.18 | K29: =ROUND(I29*J29,) -> 28771
B30: 90441400 | C30: 1/2" | D30: 450 | E30: 2600 | F30: 0.24 | G30: =E30*F30 -> 624 | H30: =I30/E30 -> 22.2 | I30: 57720 | J30: 0.18 | K30: =ROUND(I30*J30,) -> 10390
B31: PP1524 | C31: 15 | D31: 610 | E31: 2300 | F31: 0.3 | G31: =E31*F31 -> 690 | H31: =I31/E31 -> 27.75 | I31: 63825 | J31: 0.18 | K31: =ROUND(I31*J31,) -> 11489
B32: 90441600 | C32: 1/2" | D32: 600 | E32: 1600 | F32: 0.31 | G32: =E32*F32 -> 496 | H32: =I32/E32 -> 28.675 | I32: 45880 | J32: 0.18 | K32: =ROUND(I32*J32,) -> 8258
B33: PE1536 | C33: 15 | D33: 915 | E33: 1000 | F33: 0.41 | G33: =E33*F33 -> 410 | H33: =I33/E33 -> 37.925 | I33: 37925 | J33: 0.18 | K33: =ROUND(I33*J33,) -> 6827
B34: 90441800 | C34: 1/2" | D34: 900 | E34: 700 | F34: 0.44 | G34: =E34*F34 -> 308 | H34: =I34/E34 -> 40.7 | I34: 28490 | J34: 0.18 | K34: =ROUND(I34*J34,) -> 5128
B35: PE1548 | C35: 15 | D35: 1220 | E35: 50 | F35: 0.53 | G35: =E35*F35 -> 26.5 | H35: =I35/E35 -> 49.025 | I35: 2451.25 | J35: 0.18 | K35: =ROUND(I35*J35,) -> 441
B36: PP2004 | C36: 20 | D36: 100 | E36: 500 | F36: 0.13 | G36: =E36*F36 -> 65 | H36: =I36/E36 -> 12.025 | I36: 6012.5 | J36: 0.18 | K36: =ROUND(I36*J36,) -> 1082
B37: 90447000 | C37: 3/4" | D37: 240 | E37: 4000 | F37: 0.22 | G37: =E37*F37 -> 880 | H37: =I37/E37 -> 20.35 | I37: 81400 | J37: 0.18 | K37: =ROUND(I37*J37,) -> 14652
B38: PE2018 | C38: 20 | D38: 457 | E38: 400 | F38: 0.35 | G38: =E38*F38 -> 140 | H38: =I38/E38 -> 32.375 | I38: 12950 | J38: 0.18 | K38: =ROUND(I38*J38,) -> 2331
B39: 90442400 | C39: 3/4" | D39: 450 | E39: 1600 | F39: 0.36 | G39: =E39*F39 -> 576 | H39: =I39/E39 -> 33.3 | I39: 53280 | J39: 0.18 | K39: =ROUND(I39*J39,) -> 9590
B40: PE2024 | C40: 20 | D40: 610 | E40: 1000 | F40: 0.45 | G40: =E40*F40 -> 450 | H40: =I40/E40 -> 41.625 | I40: 41625 | J40: 0.18 | K40: =ROUND(I40*J40,) -> 7493
...

Sheet Page2
A1: =Page1!A1 -> MERCHANT | B1: =Page1!B1 -> INVOICE | K1: Page 2
A2: =Page1!A2 -> JAIKVIN GLOBAL | F2: =Page1!F2 -> Invoice No. | G2: =Page1!G2 -> JG/26-27/6002 DT 04.05.2026 | K2: =Page1!K2 -> Exporter's Ref.
F3: =Page1!F3 -> Date: | G3: =Page1!G3 -> 0 | K3: =Page1!K3 -> IEC AVIPS4808H
A4: =Page1!A4 -> Merchant Exporters | F4: =Page1!F4 -> Buyers Order No: | H4: =Page1!H4 -> JG/26-P/09 DT 27.04.2026
A5: =Page1!A5 -> A-101, Rajshree Royale, Navroji Lane, Ghatkopar (W), | F5: =Page1!F5 | H5: =Page1!H5 -> 0
A6: =Page1!A6 -> MUMBAI-400 086. Maharashtra (State Code : 27) | F6: =Page1!F6 -> Other Reference(s): | H6: =Page1!H6 -> 0
A7: =Page1!A7 -> Tel: 9987122600 E-Mail: aalok.shah@jaikvinglobal.com | F7: =Page1!F7 | H7: =Page1!H7 -> 0
A8: =Page1!A8 -> On Account & Risks of: | C8: =Page1!C8 -> 0 | F8: =Page1!F8 -> IRN No | G8: =Page1!G8 -> 5049ef43c7126a4c35bf29795ce49390de0338
A9: =Page1!A9 -> Messrs Corecomp Pty Ltd., | F9: =Page1!F9 -> 0 | G9: =Page1!G9 -> c2897a4b4929c186580cfacad7
A10: =Page1!A10 -> T/A G.D.Watermark | F10: =Page1!F10 -> Ack No | G10: =Page1!G10 -> 122632432448548
A11: =Page1!A11 -> 13, Tesla Link, | F11: =Page1!F11 -> 0 | G11: =Page1!G11 -> 0
A12: =Page1!A12 -> Wangara WA 6065 (Australia) | F12: =Page1!F12 -> Ack Dt | G12: =Page1!G12 -> 04-05-2026 3:51:00 PM
A13: =Page1!A13 -> Invoice of: | B13: =Page1!B13 -> PLASTIC (PP) EXTRUDED PIPES, PLASTIC (PP) | F13: =Page1!F13 -> Country of Origin | I13: =Page1!I13 -> Country of Final Destination
A14: =Page1!A14 | B14: =Page1!B14 -> & (PA) MOULDED FITTINGS AND CORRUGATED | F14: =Page1!F14 -> INDIA | I14: =Page1!I14 -> AUSTRALIA
A15: =Page1!A15 | B15: =Page1!B15 -> BOXES | F15: =Page1!F15 -> BL. NO. | G15: =Page1!G15 -> SFPM2605165498 DT. 19.05.2026 | H15: =Page1!H15 -> 0 | I15: =Page1!I15 -> 0 | J15: =Page1!J15 -> 0 | K15: =Page1!K15 -> 0
A16: =Page1!A16 -> Pre-Carraige by: | C16: =Page1!C16 -> Place of Receipt by Pre-Carraige | F16: =Page1!F16 -> Shipped Per | G16: =Page1!G16 -> CAPE SYROS VOYAGE 092E | H16: =Page1!H16 -> 0 | I16: =Page1!I16 -> 0 | J16: =Page1!J16 -> 0 | K16: =Page1!K16 -> 0
A17: =Page1!A17 | C17: =Page1!C17 -> 0 | F17: =Page1!F17 -> S/B No: | G17: =Page1!G17 -> 2945305 DT. 04.05.2026 | H17: =Page1!H17 -> 0 | I17: =Page1!I17 -> 0 | J17: =Page1!J17 -> 0 | K17: =Page1!K17 -> 0
A18: =Page1!A18 -> Shipped per: | C18: =Page1!C18 -> Port of Loading: | F18: =Page1!F18 -> Terms of Delivery: | H18: =Page1!H18 -> FOB MUMBAI
A19: =Page1!A19 -> CAPE SYROS VOYAGE 092E | C19: =Page1!C19 -> NHAVA SHEVA-MUMBAI (INDIA) | F19: =Page1!F19 -> Terms of Payment: | H19: =Page1!H19 -> D.P.SIGHT DRAFT
A20: =Page1!A20 -> Port of Discharge: | C20: =Page1!C20 -> Port of destination | F20: =Page1!F20 -> Through: | H20: =Page1!H20 -> HDFC BANK LTD, GHATKOPAR (E) BRANCH
A21: =Page1!A21 -> FREMANTLE | C21: =Page1!C21 -> FREMANTLE | F21: =Page1!F21 -> 0 | H21: =Page1!H21 -> GHATKOPAR (E), MUMBAI 400 077 (INDIA)
A22: Marks & Nos. | B22: No & Kinds of Pkgs Description of Goods | E22: Quantity | F22: Rate | G22: Amount | H22: Rate | I22: Taxable Amount | J22: GST Rate | K22: GST Amount
A23: =Page1!A23 -> GDW NOS : | B23: =Page1!B23 -> 421 PACKAGES (343 CARTONS & 78 HDP BUNDLES) CONTAINING | F23: =Page1!F23 -> FOB MUMBAI IN US$ | H23: =Page1!H23 -> FOB MUMBAI IN INR | J23: =Page1!J23 -> 0
A24: =Page1!A24 -> 2001 - 2421 | B24: =Page1!B24 -> PLASTIC (PP) EXTRUDED PIPES, PLASTIC (PP) & | H24: =Page1!H24 -> EX. RATE @ Rs.92.50 | J24: =Page1!J24 -> 0
A25: =Page1!A25 -> 2421 | B25: =Page1!B25 -> (PA) MOULDED FITTINGS & CORRUGATED BOXES | F25: BAL B/F… | G25: =Page1!G82 -> 13908.95 | I25: =Page1!I82 -> 1286577.9 | J25: =Page1!J25 -> 0 | K25: =Page1!K82 -> 231588
A26: =Page1!A26 -> 0 | B26: PLASTIC (PA) MOULDED FITTINGS (HSN CODE : 3917.4000)
A27: =Page1!A27 -> 0 | B27: CODE | C27: SIZE (IN / MM) | E27: PIECES | F27: PER 100 PCS
B28: GRC15 | C28: 15 | E28: 10000 | F28: 9.6 | G28: =E28*F28/100 -> 960 | H28: =I28/E28 -> 8.88 | I28: 88800 | J28: 0.18 | K28: =ROUND(I28*J28,) -> 15984
B29: GRC20 | C29: 20 | E29: 3000 | F29: 12 | G29: =E29*F29/100 -> 360 | H29: =I29/E29 -> 11.1 | I29: 33300 | J29: 0.18 | K29: =ROUND(I29*J29,) -> 5994
B30: GRC25 | C30: 25 | E30: 900 | F30: 15.6 | G30: =E30*F30/100 -> 140.4 | H30: =I30/E30 -> 14.43 | I30: 12987 | J30: 0.18 | K30: =ROUND(I30*J30,) -> 2338
A31: Container No. | B31: GRMFE25 | C31: 25 | E31: 1400 | F31: 33.6 | G31: =E31*F31/100 -> 470.4 | H31: =I31/E31 -> 31.08 | I31: 43512 | J31: 0.18 | K31: =ROUND(I31*J31,) -> 7832
A32: OOCU0793142 | B32: GRRS2015 | C32: 20*15 | E32: 1800 | F32: 21.6 | G32: =E32*F32/100 -> 388.8 | H32: =I32/E32 -> 19.98 | I32: 35964 | J32: 0.18 | K32: =ROUND(I32*J32,) -> 6474
B33: GRRS2520 | C33: 25*20 | E33: 1650 | F33: 24 | G33: =E33*F33/100 -> 396 | H33: =I33/E33 -> 22.2 | I33: 36630 | J33: 0.18 | K33: =ROUND(I33*J33,) -> 6593
B34: GRS25 | C34: 25 | E34: 500 | F34: 22.8 | G34: =E34*F34/100 -> 114 | H34: =I34/E34 -> 21.09 | I34: 10545 | J34: 0.18 | K34: =ROUND(I34*J34,) -> 1898
B35: GRT15 | C35: 15 | E35: 2160 | F35: 33.6 | G35: =E35*F35/100 -> 725.76 | H35: =I35/E35 -> 31.08 | I35: 67132.8 | J35: 0.18 | K35: =ROUND(I35*J35,) -> 12084
B36: GRT20 | C36: 20 | E36: 700 | F36: 40.8 | G36: =E36*F36/100 -> 285.6 | H36: =I36/E36 -> 37.74 | I36: 26418 | J36: 0.18 | K36: =ROUND(I36*J36,) -> 4755
B37: GRT25 | C37: 25 | E37: 1760 | F37: 50.4 | G37: =E37*F37/100 -> 887.04 | H37: =I37/E37 -> 46.62 | I37: 82051.2 | J37: 0.18 | K37: =ROUND(I37*J37,) -> 14769
B38: GRT32 | C38: 32 | E38: 1000 | F38: 91.2 | G38: =E38*F38/100 -> 912 | H38: =I38/E38 -> 84.36 | I38: 84360 | J38: 0.18 | K38: =ROUND(I38*J38,) -> 15185
B39: CORRUGATED BOXES (HSN CODE : 4819.1010)
B40: CODE | C40: SIZE ( MM) | E40: PIECES | F40: PER PC
...

Sheet Annx
A8: ANNEXTURE TO INVOICE
A10: Inv No & Dt | B10: =Page1!G2 -> JG/26-27/6002 DT 04.05.2026 | C10: NO OF PKGS | D10: 421 | E10: Shipment to | F10: FREMANTLE
A12: ITEM CODE | C12: QUANTITY | D12: FOB / PC US$ | F12: NET WT | G12: RATE / KG
A13: PLASTIC (PP) EXTRUDED PIPES : BOTH SIDE THREADED PIPES | C13: PCS | D13: Unit | E13: Total | F13: KGS | G13: US$
A14: PP1509 | C14: 6000 | D14: 0.07 | E14: =C14*D14 -> 420 | F14: 242.1 | G14: =E14/F14 -> 1.7348203
A15: PP1518 | C15: 7200 | D15: 0.24 | E15: =C15*D15 -> 1728 | F15: 581.04 | G15: =E15/F15 -> 2.9739777
A16: 90441400 | C16: 2600 | D16: 0.24 | E16: =C16*D16 -> 624 | F16: 209.82 | G16: =E16/F16 -> 2.9739777
A17: PP1524 | C17: 2300 | D17: 0.3 | E17: =C17*D17 -> 690 | F17: 247.25 | G17: =E17/F17 -> 2.7906977
A18: 90441600 | C18: 1600 | D18: 0.31 | E18: =C18*D18 -> 496 | F18: 172 | G18: =E18/F18 -> 2.8837209
A19: PE1536 | C19: 1000 | D19: 0.41 | E19: =C19*D19 -> 410 | F19: 161.4 | G19: =E19/F19 -> 2.5402726
A20: 90441800 | C20: 700 | D20: 0.44 | E20: =C20*D20 -> 308 | F20: 112.98 | G20: =E20/F20 -> 2.7261462
A21: PE1548 | C21: 50 | D21: 0.53 | E21: =C21*D21 -> 26.5 | F21: 10.75 | G21: =E21/F21 -> 2.4651163
A22: PP2004 | C22: 500 | D22: 0.13 | E22: =C22*D22 -> 65 | F22: 14 | G22: =E22/F22 -> 4.6428571
A23: 90447000 | C23: 4000 | D23: 0.22 | E23: =C23*D23 -> 880 | F23: 256 | G23: =E23/F23 -> 3.4375
A24: PE2018 | C24: 400 | D24: 0.35 | E24: =C24*D24 -> 140 | F24: 52 | G24: =E24/F24 -> 2.6923077
A25: 90442400 | C25: 1600 | D25: 0.36 | E25: =C25*D25 -> 576 | F25: 208 | G25: =E25/F25 -> 2.7692308
A26: PE2024 | C26: 1000 | D26: 0.45 | E26: =C26*D26 -> 450 | F26: 170 | G26: =E26/F26 -> 2.6470588
A27: 90442700 | C27: 500 | D27: 0.56 | E27: =C27*D27 -> 280 | F27: 110 | G27: =E27/F27 -> 2.5454545
A28: PP2508 | C28: 600 | D28: 0.24 | E28: =C28*D28 -> 144 | F28: 43.2 | G28: =E28/F28 -> 3.3333333
A29: 90448000 | C29: 500 | D29: 0.35 | E29: =C29*D29 -> 175 | F29: 49.3 | G29: =E29/F29 -> 3.5496957
A30: PE2515 | C30: 1000 | D30: 0.39 | E30: =C30*D30 -> 390 | F30: 137 | G30: =E30/F30 -> 2.8467153
A31: PE2518 | C31: 2300 | D31: 0.45 | E31: =C31*D31 -> 1035 | F31: 391 | G31: =E31/F31 -> 2.6470588
A32: 90443400 | C32: 800 | D32: 0.46 | E32: =C32*D32 -> 368 | F32: 136 | G32: =E32/F32 -> 2.7058824
A33: PE2524 | C33: 400 | D33: 0.58 | E33: =C33*D33 -> 232 | F33: 94 | G33: =E33/F33 -> 2.4680851
A34: 90443600 | C34: 500 | D34: 0.6 | E34: =C34*D34 -> 300 | F34: 117.5 | G34: =E34/F34 -> 2.5531915
A35: 90443700 | C35: 500 | D35: 0.72 | E35: =C35*D35 -> 360 | F35: 143 | G35: =E35/F35 -> 2.5174825
A36: 90443900 | C36: 200 | D36: 1.66 | E36: =C36*D36 -> 332 | F36: 132 | G36: =E36/F36 -> 2.5151515
A37: PE3206 | C37: 600 | D37: 0.28 | E37: =C37*D37 -> 168 | F37: 45 | G37: =E37/F37 -> 3.7333333
A38: 90446200 | C38: 300 | D38: 0.29 | E38: =C38*D38 -> 87 | F38: 22.5 | G38: =E38/F38 -> 3.8666667
A39: PE3218 | C39: 100 | D39: 0.6 | E39: =C39*D39 -> 60 | F39: 22.5 | G39: =E39/F39 -> 2.6666667
A40: 90446400 | C40: 100 | D40: 0.63 | E40: =C40*D40 -> 63 | F40: 22.5 | G40: =E40/F40 -> 2.8
A41: 90446600 | C41: 200 | D41: 0.8 | E41: =C41*D41 -> 160 | F41: 60 | G41: =E41/F41 -> 2.6666667
A42: PE3230 | C42: 60 | D42: 0.93 | E42: =C42*D42 -> 55.8 | F42: 19.1 | G42: =E42/F42 -> 2.921466
A43: 90446700 | C43: 100 | D43: 1.15 | E43: =C43*D43 -> 115 | F43: 45 | G43: =E43/F43 -> 2.5555556
A44: 90446800 | C44: 50 | D44: 2.2 | E44: =C44*D44 -> 110 | F44: 45.8 | G44: =E44/F44 -> 2.4017467
A45: 90447200 | C45: 300 | D45: 0.34 | E45: =C45*D45 -> 102 | F45: 29.9 | G45: =E45/F45 -> 3.4113712
A46: PE4008 | C46: 150 | D46: 0.44 | E46: =C46*D46 -> 66 | F46: 20.8 | G46: =E46/F46 -> 3.1730769
A47: PE4018 | C47: 100 | D47: 0.81 | E47: =C47*D47 -> 81 | F47: 29.9 | G47: =E47/F47 -> 2.7090301
A48: 90447400 | C48: 200 | D48: 0.86 | E48: =C48*D48 -> 172 | F48: 59.8 | G48: =E48/F48 -> 2.8762542
A49: PE5006 | C49: 150 | D49: 0.41 | E49: =C49*D49 -> 61.5 | F49: 21 | G49: =E49/F49 -> 2.9285714
...
