Workbook

Sheet Sheet1
A1: PACKING LIST
A2: JAIKVIN GLOBAL | E2: Invoice No. | G2: JG/26-27/6002 DT 04.05.2026
A4: Merchant Exporters | E4: Buyers Order No: | G4: 03320 DT 08.08.2025, 03455 DT.04.11.2025,
A5: A-101, Rajshree Royale, Navroji Lane, Ghatkopar (W), | G5: 03539 DT 08.01.2026, 03583 DT 12.02.2026,
A6: MUMBAI-400 086. Maharashtra (State Code : 27) | G6: 03605 DT. 25.02.2026, 03616 DT 04.03.2026,
A7: Tel: 9987122600 E-Mail: aalok.shah@jaikvinglobal.com | G7: 03658 DT. 02.04.2026
A8: On Account & risks of | E8: BL : 'SFPM2605165498 DT. 19.05.2026
A9: Messrs. Corecomp Pty Ltd.,
A10: T/A G.D.Watermark, | E10: Shipped per: CAPE SYROS VOYAGE 092E
A11: 13, Tesla Link,
A12: Wangara WA 6065 (Australia)
E13: Country of Origin | H13: Country of Final Destination
E14: INDIA | H14: AUSTRALIA
E15: Shipping Marks | G15: CONTAINER NO :
A16: Pre-Carraige by: | D16: Place of Receipt by Pre-Carraige | E16: G.D.W. | G16: OOCU0793142
E17: 2001 - 2421 / 2421
A18: Shipped per: | D18: Port of Loading: | G18: SEAL NO :
D19: NHAVA SHEVA-MUMBAI (INDIA) | G19: IND-0054079
A20: Port of Discharge: | D20: Final Destination:
A21: FREMANTLE | D21: FREMANTLE
A22: Sr.Nos. | B22: No. & Kind of Pkgs Description of Goods | G22: Quantity | H22: WEIGHT
B23: 421 PACKAGES (343 CARTONS & 78 HDP BUNDLES) CONTAINING PP EXTRUDED | H23: NETT | I23: GROSS
B24: PIPES, PP & NYLON MOULDED FITTINGS & CORRUGATED BOXES | H24: KGS | I24: KGS
B25: PP EXTRUDED PIPES : BOTH SIDE THREADED PIPES
A26: SR NOS | B26: CODE | C26: SIZE (MM/IN) | D26: LEN (MM) | E26: Qty/Pkg-Pcs | F26: PKGS | G26: PIECES
A27: 2001-2015 | B27: PP1509 | C27: 15 | D27: 225 | E27: 400 | F27: =G27/E27 -> 15 | G27: 6000 | H27: 242.1 | I27: 253
A28: 2016-2051 | B28: PP1518 | C28: 15 | D28: 457 | E28: 200 | F28: =G28/E28 -> 36 | G28: 7200 | H28: 581.04 | I28: 609.51
A29: 2052-2064 | B29: 90441400 | C29: 1/2" | D29: 450 | E29: 200 | F29: =G29/E29 -> 13 | G29: 2600 | H29: 209.82 | I29: 220.35
A30: 2065-2087 | B30: PP1524 | C30: 15 | D30: 610 | E30: 100 | F30: =G30/E30 -> 23 | G30: 2300 | H30: 247.25 | I30: 267.72
A31: 2088-2103 | B31: 90441600 | C31: 1/2" | D31: 600 | E31: 100 | F31: =G31/E31 -> 16 | G31: 1600 | H31: 172 | I31: 186.24
A32: 2104-2113 | B32: PE1536 | C32: 15 | D32: 915 | E32: 100 | F32: =G32/E32 -> 10 | G32: 1000 | H32: 161.4 | I32: 169.5
A33: 2114-2120 | B33: 90441800 | C33: 1/2" | D33: 900 | E33: 100 | F33: =G33/E33 -> 7 | G33: 700 | H33: 112.98 | I33: 118.65
A34: 2121-2121 | B34: PE1548 | C34: 15 | D34: 1220 | E34: 50 | F34: =G34/E34 -> 1 | G34: 50 | H34: 10.75 | I34: 11.64
A35: 2122-2122 | B35: PP2004 | C35: 20 | D35: 100 | E35: 500 | F35: =G35/E35 -> 1 | G35: 500 | H35: 14 | I35: 15.24
A36: 2123-2138 | B36: 90447000 | C36: 3/4" | D36: 240 | E36: 250 | F36: =G36/E36 -> 16 | G36: 4000 | H36: 256 | I36: 276.8
A37: 2139-2142 | B37: PE2018 | C37: 20 | D37: 457 | E37: 100 | F37: =G37/E37 -> 4 | G37: 400 | H37: 52 | I37: 55.2
A38: 2143-2158 | B38: 90442400 | C38: 3/4" | D38: 450 | E38: 100 | F38: =G38/E38 -> 16 | G38: 1600 | H38: 208 | I38: 220.8
A39: 2159-2168 | B39: PE2024 | C39: 20 | D39: 610 | E39: 100 | F39: =G39/E39 -> 10 | G39: 1000 | H39: 170 | I39: 183
A40: 2169-2173 | B40: 90442700 | C40: 3/4" | D40: 750 | E40: 100 | F40: =G40/E40 -> 5 | G40: 500 | H40: 110 | I40: 115
A41: 2174-2177 | B41: PP2508 | C41: 25 | D41: 200 | E41: 150 | F41: =G41/E41 -> 4 | G41: 600 | H41: 43.2 | I41: 46.88
...

Sheet Sheet2
A1: PACKING LIST | H1: Page 2
A2: =Sheet1!A2 -> JAIKVIN GLOBAL | E2: Invoice No. | G2: =Sheet1!G2 -> JG/26-27/6002 DT 04.05.2026
G3: =Sheet1!G3 -> 0
A4: =Sheet1!A4 -> Merchant Exporters | E4: Buyers Order No: | G4: 03320 DT 08.08.2025, 03455 DT.04.11.2025,
A5: =Sheet1!A5 -> A-101, Rajshree Royale, Navroji Lane, Ghatkopar (W), | G5: 03539 DT 08.01.2026, 03583 DT 12.02.2026,
A6: =Sheet1!A6 -> MUMBAI-400 086. Maharashtra (State Code : 27) | G6: 03605 DT. 25.02.2026, 03616 DT 04.03.2026,
A7: =Sheet1!A7 -> Tel: 9987122600 E-Mail: aalok.shah@jaikvinglobal.com | G7: 03658 DT. 02.04.2026
A8: =Sheet1!A8 -> On Account & risks of | D8: =Sheet1!D8 -> 0 | E8: =Sheet1!E8 -> BL : 'SFPM2605165498 DT. 19.05.2026
A9: =Sheet1!A9 -> Messrs. Corecomp Pty Ltd., | E9: =Sheet1!E9 -> 0
A10: =Sheet1!A10 -> T/A G.D.Watermark, | E10: =Sheet1!E10 -> Shipped per: CAPE SYROS VOYAGE 092E
A11: =Sheet1!A11 -> 13, Tesla Link, | E11: =Sheet1!E11 -> 0
A12: =Sheet1!A12 -> Wangara WA 6065 (Australia) | E12: =Sheet1!E12 -> 0
A13: =Sheet1!A13 -> 0 | E13: =Sheet1!E13 -> Country of Origin | H13: =Sheet1!H13 -> Country of Final Destination
A14: =Sheet1!A14 -> 0 | E14: =Sheet1!E14 -> INDIA | H14: =Sheet1!H14 -> AUSTRALIA
A15: =Sheet1!A15 -> 0 | E15: =Sheet1!E15 -> Shipping Marks | G15: =Sheet1!G15 -> CONTAINER NO :
A16: =Sheet1!A16 -> Pre-Carraige by: | D16: =Sheet1!D16 -> Place of Receipt by Pre-Carraige | E16: =Sheet1!E16 -> G.D.W. | G16: =Sheet1!G16 -> OOCU0793142
A17: =Sheet1!A17 | D17: =Sheet1!D17 -> 0 | E17: =Sheet1!E17 -> 2001 - 2421 / 2421 | G17: =Sheet1!G17
A18: =Sheet1!A18 -> Shipped per: | D18: =Sheet1!D18 -> Port of Loading: | E18: =Sheet1!E18 -> 0 | G18: =Sheet1!G18 -> SEAL NO :
A19: =Sheet1!A19 -> 0 | D19: =Sheet1!D19 -> NHAVA SHEVA-MUMBAI (INDIA) | E19: =Sheet1!E19 -> 0 | G19: =Sheet1!G19 -> IND-0054079
A20: =Sheet1!A20 -> Port of Discharge: | D20: =Sheet1!D20 -> Final Destination: | E20: =Sheet1!E20 -> 0 | G20: =Sheet1!G20 -> 0
A21: =Sheet1!A21 -> FREMANTLE | D21: =Sheet1!D21 -> FREMANTLE | E21: =Sheet1!E21 -> 0 | G21: =Sheet1!G21 -> 0
A22: Sr.Nos. | B22: No. & Kind of Pkgs Description of Goods | G22: Quantity | H22: WEIGHT
B23: =Sheet1!B23 -> 421 PACKAGES (343 CARTONS & 78 HDP BUNDLES) CONTAINING PP EXTRUDED | H23: NETT | I23: GROSS
B24: =Sheet1!B24 -> PIPES, PP & NYLON MOULDED FITTINGS & CORRUGATED BOXES | H24: KGS | I24: KGS
B25: PP MOULDED FITTINGS | F25: BAL B/F… | H25: =Sheet1!H76 -> 4838.94 | I25: =Sheet1!I76 -> 5138.09
A26: SR NOS | B26: CODE | C26: SIZE (MM) | E26: Qty/Ctn-Pcs | F26: CARTONS | G26: PIECES
A27: 2309-2309 | B27: PET1512 | C27: 15 | E27: 300 | F27: =G27/E27 -> 1 | G27: 300 | H27: 11.5 | I27: 12.5
A28: 2310-2311 | B28: PP1501 / 5 | C28: 15 | E28: 2000 | F28: =G28/E28 -> 2 | G28: 4000 | H28: 17.6 | I28: 19.6
B29: PA MOULDED FITTINGS
A30: SR NOS | B30: CODE | C30: SIZE (MM) | E30: Qty/Ctn-Pcs | F30: CARTONS | G30: PIECES
A31: 2312-2315 | B31: GRC15 | C31: 15 | E31: 2500 | F31: =G31/E31 -> 4 | G31: 10000 | H31: 100 | I31: 106
A32: 2316-2317 | B32: GRC20 | C32: 20 | E32: 1500 | F32: =G32/E32 -> 2 | G32: 3000 | H32: 36 | I32: 39.4
A33: 2318-2318 | B33: GRC25 | C33: 25 | E33: 900 | F33: =G33/E33 -> 1 | G33: 900 | H33: 16.7 | I33: 18
A34: 2319-2322 | B34: GRMFE25 | C34: 25 | E34: 350 | F34: =G34/E34 -> 4 | G34: 1400 | H34: 51.6 | I34: 56
A35: 2323-2324 | B35: GRRS2015 | C35: 20*15 | E35: 900 | F35: =G35/E35 -> 2 | G35: 1800 | H35: 32 | I35: 35
A36: 2325-2327 | B36: GRRS2520 | C36: 25*20 | E36: 550 | F36: =G36/E36 -> 3 | G36: 1650 | H36: 42.9 | I36: 46.5
A37: 2328-2328 | B37: GRS25 | C37: 25 | E37: 500 | F37: =G37/E37 -> 1 | G37: 500 | H37: 16.3 | I37: 17.5
A38: 2329-2332 | B38: GRT15 | C38: 15 | E38: 540 | F38: =G38/E38 -> 4 | G38: 2160 | H38: 54 | I38: 58.8
A39: 2333-2334 | B39: GRT20 | C39: 20 | E39: 350 | F39: =G39/E39 -> 2 | G39: 700 | H39: 28.2 | I39: 30.4
A40: 2335-2342 | B40: GRT25 | C40: 25 | E40: 220 | F40: =G40/E40 -> 8 | G40: 1760 | H40: 112 | I40: 120
...

Sheet Risers
A1: PO NO. 03455 DT.04.11.2025, 03539 DT.08.01.2026, 03583 DT.12.02.2026, 03616 DT. 04.03.2026, 03658 DT. 02.04.2026
A2: CODE | B2: GD CODE | C2: GL CODE | D2: SIZE | E2: LENGTH | F2: PACKING | H2: DESCRIPTION | I2: QUANTITY
A3: 15 MM (1/2") | B3: 15 MM (1/2") | D3: MM / IN | E3: MM | F3: UNIT | G3: BOX | I3: PCS | J3: BOX
A4: PP1509 | B4: PP1509 | C4: 8109-04 | D4: 15 | E4: 225 | F4: 10 | G4: 400 | H4: PP 1509 P/RISER M X M 225 X 15MM | I4: 6000 | J4: =$I4/$G4 -> 15
A5: PP1518 | B5: PP1518 | C5: 8109-04 | D5: 15 | E5: 457 | F5: 10 | G5: 200 | H5: PP1518 P/RISER M X M 457 X 15MM | I5: 7200 | J5: =$I5/$G5 -> 36
A6: 90441400 | B6: PP1518PH | C6: 8109-04 | D6: 1/2" | E6: 450 | F6: 10 | G6: 200 | H6: 90441400 P/RISER M X M 1/2" X 1/2" X 450MM | I6: 2600 | J6: =$I6/$G6 -> 13
A7: PP1524 | B7: PP1524 | C7: 8109-04 | D7: 15 | E7: 610 | F7: 10 | G7: 100 | H7: PP1524 P/RISER M X M 610 X 15MM | I7: 2300 | J7: =$I7/$G7 -> 23
A8: 90441600 | B8: PP1524PH | C8: 8109-04 | D8: 1/2" | E8: 600 | F8: 10 | G8: 100 | H8: 90441600 P/RISER M X M 1/2" X 1/2" X 600MM | I8: 1600 | J8: =$I8/$G8 -> 16
A9: PE1536 | B9: PE1536 | C9: 8109-05 | D9: 15 | E9: 915 | F9: 10 | G9: 100 | H9: PE 1536 P/RISER M X M 915 X 15MM | I9: 1000 | J9: =$I9/$G9 -> 10
A10: 90441800 | B10: PE1536PH | C10: 8109-05 | D10: 1/2" | E10: 900 | F10: 10 | G10: 100 | H10: 90441800 P/RISER M X M 1/2" X 1/2" X 900MM | I10: 700 | J10: =$I10/$G10 -> 7
A11: PE1548 | B11: PE1548 | C11: 8109-05 | D11: 15 | E11: 1220 | F11: 10 | G11: 50 | H11: PE 1548 P/RISER M X M 1220 X 15MM | I11: 50 | J11: =$I11/$G11 -> 1
A12: 20MM(3/4") | B12: 20MM(3/4")
A13: PP2004 | B13: PP2004 | C13: 8109-04 | D13: 20 | E13: 100 | F13: 10 | G13: 500 | H13: PP 2004 P/RISER M X M 100 X 20MM | I13: 500 | J13: =$I13/$G13 -> 1
A14: 90447000 | B14: PP2010PH | C14: 8109-04 | D14: 3/4" | E14: 240 | F14: 10 | G14: 250 | H14: 90447000 SPACER METER 3/4" X 3/4" X 240MM | I14: 4000 | J14: =$I14/$G14 -> 16
A15: PE2018 | B15: PE2018 | C15: 8109-05 | D15: 20 | E15: 457 | F15: 10 | G15: 100 | H15: PE 2018 P/RISER M X M 457 X 20MM | I15: 400 | J15: =$I15/$G15 -> 4
A16: 90442400 | B16: PE2018PH | C16: 8109-05 | D16: 3/4" | E16: 450 | F16: 10 | G16: 100 | H16: 90442400 P/RISER M X M 3/4" X 3/4" X 450MM | I16: 1600 | J16: =$I16/$G16 -> 16
A17: PE2024 | B17: PE2024 | C17: 8109-05 | D17: 20 | E17: 610 | F17: 10 | G17: 100 | H17: PE 2024 P/RISER M X M 610 X 20MM | I17: 1000 | J17: =$I17/$G17 -> 10
A18: 90442700 | B18: PE2030PH | C18: 8109-05 | D18: 3/4" | E18: 750 | F18: 10 | G18: 100 | H18: 90442700 P/RISER M X M 3/4" X 3/4" X 750MM | I18: 500 | J18: =$I18/$G18 -> 5
A19: 25mm(1") | B19: 25mm(1")
A20: PP2508 | B20: PP2508 | C20: 8109-04 | D20: 25 | E20: 200 | F20: 10 | G20: 150 | H20: PP 2508 P/RISER M X M 200 X 25MM | I20: 600 | J20: =$I20/$G20 -> 4
A21: 90448000 | B21: PP2511PH | C21: 8109-05 | D21: 1" | E21: 270 | F21: 10 | G21: 100 | H21: 90448000 SPACER METER 1" X 1" X 270MM | I21: 500 | J21: =$I21/$G21 -> 5
A22: PE2515 | B22: PE2515 | C22: 8109-05 | D22: 25 | E22: 375 | F22: 10 | G22: 100 | H22: PE 2515 P/RISER M X M 375 X 25MM | I22: 1000 | J22: =$I22/$G22 -> 10
A23: PE2518 | B23: PE2518 | C23: 8109-05 | D23: 25 | E23: 457 | F23: 10 | G23: 100 | H23: PE2518 P/RISER M X M 457 X 25MM | I23: 2300 | J23: =$I23/$G23 -> 23
A24: 90443400 | B24: PE2518PH | C24: 8109-05 | D24: 1" | E24: 450 | F24: 10 | G24: 100 | H24: 90443400 P/RISER M X M 1" X 1" X 450MM | I24: 800 | J24: =$I24/$G24 -> 8
A25: PE2524 | B25: PE2524 | C25: 8109-05 | D25: 25 | E25: 610 | F25: 10 | G25: 50 | H25: PE 2524 P/RISER M X M 610 X 25MM | I25: 400 | J25: =$I25/$G25 -> 8
A26: 90443600 | B26: PE2524PH | C26: 8109-05 | D26: 1" | E26: 600 | F26: 10 | G26: 50 | H26: 90443600 P/RISER M X M 1" X 1" X 600MM | I26: 500 | J26: =$I26/$G26 -> 10
A27: 90443700 | B27: PE2530PH | C27: 8109-05 | D27: 1" | E27: 750 | F27: 10 | G27: 50 | H27: 90443700 P/RISER M X M 1" X 1" X 750MM | I27: 500 | J27: =$I27/$G27 -> 10
A28: 90443900 | B28: PE2572PH | C28: 8109-05 | D28: 1" | E28: 1800 | F28: 10 | G28: 50 | H28: 90443900 P/RISER M X M 1" X 1" X 1800MM | I28: 200 | J28: =$I28/$G28 -> 4
A29: 32 MM (1.1/4") | B29: 32 MM (1.1/4")
A30: PE3206 | B30: PE3206 | C30: 8109-05 | D30: 32 | E30: 150 | F30: 10 | G30: 300 | H30: PE 3206 P/RISER M X M 150 X 32MM | I30: 600 | J30: =$I30/$G30 -> 2
A31: 90446200 | B31: PE3206PH | C31: 8109-05 | D31: 1-1/4" | E31: 150 | F31: 10 | G31: 300 | H31: 90446200 P/RISER M X M 1-1/4" x 1-1/4" x 150MM | I31: 300 | J31: =$I31/$G31 -> 1
A32: PE3218 | B32: PE3218 | C32: 8109-05 | D32: 32 | E32: 450 | F32: 10 | G32: 100 | H32: PE 3218 P/RISER M X M 450 X 32MM | I32: 100 | J32: =$I32/$G32 -> 1
A33: 90446400 | B33: PE3218PH | C33: 8109-05 | D33: 1-1/4" | E33: 450 | F33: 10 | G33: 100 | H33: 90446400 P/RISER M X M 1-1/4" x 1-1/4" x 450MM | I33: 100 | J33: =$I33/$G33 -> 1
A34: 90446600 | B34: PE3224PH | C34: 8109-05 | D34: 1-1/4" | E34: 600 | F34: 10 | G34: 100 | H34: 90446600 P/RISER M X M 1-1/4" x 1-1/4" x 600MM | I34: 200 | J34: =$I34/$G34 -> 2
A35: PE3230 | B35: PE3230 | C35: 8109-05 | D35: 32 | E35: 750 | F35: 10 | G35: 60 | H35: PE 3230 P/RISER M X M 750 X 32MM | I35: 60 | J35: =$I35/$G35 -> 1
A36: 90446700 | B36: PE3236PH | C36: 8109-05 | D36: 1-1/4" | E36: 900 | F36: 10 | G36: 50 | H36: 90446700 P/RISER M X M 1-1/4" x 1-1/4" x 900MM | I36: 100 | J36: =$I36/$G36 -> 2
A37: 90446800 | B37: PE3272PH | C37: 8109-05 | D37: 1-1/4" | E37: 1800 | F37: 5 | G37: 25 | H37: 90446800 P/RISER M X M 1-1/4" x 1-1/4" x 1800MM | I37: 50 | J37: =$I37/$G37 -> 2
A38: 40 MM (1.1/2") | B38: 40 MM (1.1/2")
A39: 90447200 | B39: PE4006PH | C39: 8109-05 | D39: 1-1/2" | E39: 150 | F39: 10 | G39: 300 | H39: 90447200 P/RISER M X M 1-1/2" x 1-1/2" x 150MM | I39: 300 | J39: =$I39/$G39 -> 1
A40: PE4008 | B40: PE4008 | C40: 8109-05 | D40: 40 | E40: 200 | F40: 10 | G40: 150 | H40: PE 4008 P/RISER M X M 200 X 40MM | I40: 150 | J40: =$I40/$G40 -> 1
...

Sheet PP Fittings
A1: PO NOS : 03658 DT 02.04.2026
A2: CODE | B2: GL CODE | C2: SIZE | D2: LENGTH | E2: PACKING | G2: DESCRIPTION | H2: Quantity
C3: MM | D3: MM | E3: UNIT | F3: BOX | H3: Pcs | I3: Box
A4: PET1512 | B4: 8109-04 | C4: 15 | D4: 300 | E4: 10 | F4: 300 | G4: PET 1512 Full Thread Riser 300 X 15MM | H4: 300 | I4: =H4/F4 -> 1
A5: PP1501 / 5 | B5: 8109-04 | C5: 15 | D5: 25 | E5: 5 | F5: 2000 | G5: PP 1501 P/RISER M X M 25 x 15MM | H5: 4000 | I5: =H5/F5 -> 2
H6: =SUBTOTAL(9,H4:H5) -> 4300 | I6: =SUBTOTAL(9,I4:I5) -> 3

Sheet Nylon Fittings
A1: PO NOS : 03320 DT 08.08.2025, 03539 DT 08.01.2026, 03583 DT 12.02.2026, 03616 DT 04.03.2026, 03658 DT. 02.04.2026
A2: GD CODE | B2: GL CODE | C2: SIZE | D2: PACKING | F2: DESCRIPTION | G2: QUANTITY
C3: MM | D3: UNIT | E3: BOX | G3: PCS | H3: BOX
A4: GRC15 | B4: 8109-05 | C4: 15 | D4: 10 | E4: 2500 | F4: 15MM CAP | G4: 10000 | H4: =G4/E4 -> 4
A5: GRC20 | B5: 8109-05 | C5: 20 | D5: 10 | E5: 1500 | F5: 20MM CAP | G5: 3000 | H5: =G5/E5 -> 2
A6: GRC25 | B6: 8109-05 | C6: 25 | D6: 10 | E6: 900 | F6: 25MM CAP | G6: 900 | H6: =G6/E6 -> 1
A7: GRMFE25 | B7: 8109-05 | C7: 25 | D7: 10 | E7: 350 | F7: 25MM M/F ELBOW | G7: 1400 | H7: =G7/E7 -> 4
A8: GRRS2015 | B8: 8109-05 | C8: 20*15 | D8: 10 | E8: 900 | F8: 20 X 15MM RED. SOCKET | G8: 1800 | H8: =G8/E8 -> 2
A9: GRRS2520 | B9: 8109-05 | C9: 25*20 | D9: 10 | E9: 550 | F9: 25 X 20MM RED. SOCKET | G9: 1650 | H9: =G9/E9 -> 3
A10: GRS25 | B10: 8109-05 | C10: 25 | D10: 10 | E10: 500 | F10: 25MM SOCKET | G10: 500 | H10: =G10/E10 -> 1
A11: GRT15 | B11: 8109-05 | C11: 15 | D11: 10 | E11: 540 | F11: 15MM TEE | G11: 2160 | H11: =G11/E11 -> 4
A12: GRT20 | B12: 8109-05 | C12: 20 | D12: 10 | E12: 350 | F12: 20MM TEE | G12: 700 | H12: =G12/E12 -> 2
A13: GRT25 | B13: 8109-05 | C13: 25 | D13: 10 | E13: 220 | F13: 25MM TEE | G13: 1760 | H13: =G13/E13 -> 8
A14: GRT32 | B14: 8109-05 | C14: 32 | D14: 10 | E14: 100 | F14: 32MM TEE | G14: 1000 | H14: =G14/E14 -> 10
G15: =SUBTOTAL(9,G4:G14) -> 24870 | H15: =SUBTOTAL(9,H4:H14) -> 41

Sheet Boxes
A1: PO NO. 03605 DT. 25.02.2026
A2: CODE | B2: SIZE | E2: PACKING | F2: DESCRIPTION | G2: QUANTITY
A3: 3 PLY BROAD FLUTE | B3: MM | C3: MM | D3: MM | E3: S/W BDL | G3: PCS | H3: BDL
A4: GD3 | B4: 570 | C4: 368 | D4: 178 | E4: 15 | F4: CORRUGATED DISPLAY BOXES | G4: 750 | H4: =$G4/$E4 -> 50
A5: GD4 | B5: 570 | C5: 368 | D5: 267 | E5: 15 | F5: CORRUGATED DISPLAY BOXES | G5: 270 | H5: =$G5/$E5 -> 18
A6: GD4 | B6: 570 | C6: 368 | D6: 267 | E6: 7 | F6: CORRUGATED DISPLAY BOXES | G6: 7 | H6: =$G6/$E6 -> 1
G7: =SUBTOTAL(9,G4:G6) -> 1027 | H7: =SUBTOTAL(9,H4:H6) -> 69
