Workbook

Sheet Page1
A1: MERCHANT | B1: INVOICE
A2: JAIKVIN GLOBAL | F2: Invoice No. | G2: JG/26-27/6002 DT 04.05.2026 | K2: Exporter's Ref.
F3: Date: | K3: IEC AVIPS4808H
A4: Merchant Exporters | F4: Buyers Order No: | H4: 03320 DT 08.08.2025, 03455 DT.04.11.2025,
A5: A-101, Rajshree Royale, Navroji Lane, Ghatkopar (W), | H5: 03539 DT 08.01.2026, 03583 DT 12.02.2026,
A6: MUMBAI-400 086. Maharashtra (State Code : 27) | H6: 03605 DT. 25.02.2026, 03616 DT 04.03.2026,
A7: Tel: 9987122600 E-Mail: aalok.shah@jaikvinglobal.com | H7: 03658 DT. 02.04.2026
A8: On Account & Risks of: | F8: BL. NO. | G8: SFPM2605165498 DT. 19.05.2026
A9: Messrs Corecomp Pty Ltd.,
A10: T/A G.D.Watermark | F10: Shipped Per | G10: CAPE SYROS VOYAGE 092E
A11: 13, Tesla Link,
A12: Wangara WA 6065 (Australia) | F12: S/B No: | G12: 2945305 DT. 04.05.2026
A13: Invoice of: | B13: PP EXTRUDED PIPES, PP & NYLON MOULDED | F13: Country of Origin | I13: Country of Final Destination
B14: FITTINGS AND CORRUGATED BOXES | F14: INDIA | I14: AUSTRALIA
A16: Pre-Carraige by: | C16: Place of Receipt by Pre-Carraige | F16: Terms of Delivery: | H16: FOB MUMBAI
A18: Shipped per: | C18: Port of Loading: | F18: Terms of Payment: | H18: D.P.SIGHT DRAFT
A19: =G10 -> CAPE SYROS VOYAGE 092E | C19: NHAVA SHEVA-MUMBAI (INDIA)
A20: Port of Discharge: | C20: Port of destination | F20: Through: | H20: HDFC BANK LTD, GHATKOPAR (E) BRANCH
A21: FREMANTLE | C21: FREMANTLE | H21: GHATKOPAR (E), MUMBAI 400 077 (INDIA)
A22: Marks & Nos. | B22: No & Kinds of Pkgs Description of Goods | I22: Quantity | J22: Rate | K22: Amount
A23: GDW NOS : | B23: 421 PACKAGES (343 CARTONS & 78 HDP BUNDLES) CONTAINING | J23: FOB MUMBAI IN US$
A24: 2001 - 2421 | B24: PP EXTRUDED PIPES, PP & NYLON MOULDED FITTINGS & CORRUGATED BOXES
A25: 2421
B26: PP EXTRUDED PIPES : BOTH SIDE THREADED PIPES
B27: CODE | C27: SIZE (IN / MM) | D27: LEN (MM) | I27: PIECES | J27: PER PC
B28: PP1509 | C28: 15 | D28: 225 | I28: 6000 | J28: 0.07 | K28: =I28*J28 -> 420
B29: PP1518 | C29: 15 | D29: 457 | I29: 7200 | J29: 0.24 | K29: =I29*J29 -> 1728
B30: 90441400 | C30: 1/2" | D30: 450 | I30: 2600 | J30: 0.24 | K30: =I30*J30 -> 624
B31: PP1524 | C31: 15 | D31: 610 | I31: 2300 | J31: 0.3 | K31: =I31*J31 -> 690
B32: 90441600 | C32: 1/2" | D32: 600 | I32: 1600 | J32: 0.31 | K32: =I32*J32 -> 496
B33: PE1536 | C33: 15 | D33: 915 | I33: 1000 | J33: 0.41 | K33: =I33*J33 -> 410
B34: 90441800 | C34: 1/2" | D34: 900 | I34: 700 | J34: 0.44 | K34: =I34*J34 -> 308
B35: PE1548 | C35: 15 | D35: 1220 | I35: 50 | J35: 0.53 | K35: =I35*J35 -> 26.5
B36: PP2004 | C36: 20 | D36: 100 | I36: 500 | J36: 0.13 | K36: =I36*J36 -> 65
B37: 90447000 | C37: 3/4" | D37: 240 | I37: 4000 | J37: 0.22 | K37: =I37*J37 -> 880
B38: PE2018 | C38: 20 | D38: 457 | I38: 400 | J38: 0.35 | K38: =I38*J38 -> 140
B39: 90442400 | C39: 3/4" | D39: 450 | I39: 1600 | J39: 0.36 | K39: =I39*J39 -> 576
B40: PE2024 | C40: 20 | D40: 610 | I40: 1000 | J40: 0.45 | K40: =I40*J40 -> 450
B41: 90442700 | C41: 3/4" | D41: 750 | I41: 500 | J41: 0.56 | K41: =I41*J41 -> 280
B42: PP2508 | C42: 25 | D42: 200 | I42: 600 | J42: 0.24 | K42: =I42*J42 -> 144
...

Sheet Page2
A1: =Page1!A1 -> MERCHANT | B1: =Page1!B1 -> INVOICE | K1: Page 2
A2: =Page1!A2 -> JAIKVIN GLOBAL | F2: =Page1!F2 -> Invoice No. | G2: =Page1!G2 -> JG/26-27/6002 DT 04.05.2026 | K2: =Page1!K2 -> Exporter's Ref.
F3: =Page1!F3 -> Date: | G3: =Page1!G3 -> 0 | K3: =Page1!K3 -> IEC AVIPS4808H
A4: =Page1!A4 -> Merchant Exporters | F4: Buyers Order No: | H4: 03320 DT 08.08.2025, 03455 DT.04.11.2025,
A5: =Page1!A5 -> A-101, Rajshree Royale, Navroji Lane, Ghatkopar (W), | H5: 03539 DT 08.01.2026, 03583 DT 12.02.2026,
A6: =Page1!A6 -> MUMBAI-400 086. Maharashtra (State Code : 27) | H6: 03605 DT. 25.02.2026, 03616 DT 04.03.2026,
A7: =Page1!A7 -> Tel: 9987122600 E-Mail: aalok.shah@jaikvinglobal.com | H7: 03658 DT. 02.04.2026
A8: =Page1!A8 -> On Account & Risks of: | C8: =Page1!C8 -> 0 | F8: =Page1!F8 -> BL. NO. | G8: =Page1!G8 -> SFPM2605165498 DT. 19.05.2026
A9: =Page1!A9 -> Messrs Corecomp Pty Ltd., | F9: =Page1!F9 -> 0 | G9: =Page1!G9 -> 0
A10: =Page1!A10 -> T/A G.D.Watermark | F10: =Page1!F10 -> Shipped Per | G10: =Page1!G10 -> CAPE SYROS VOYAGE 092E
A11: =Page1!A11 -> 13, Tesla Link, | F11: =Page1!F11 -> 0 | G11: =Page1!G11 -> 0
A12: =Page1!A12 -> Wangara WA 6065 (Australia) | F12: =Page1!F12 -> S/B No: | G12: =Page1!G12 -> 2945305 DT. 04.05.2026
A13: =Page1!A13 -> Invoice of: | B13: =Page1!B13 -> PP EXTRUDED PIPES, PP & NYLON MOULDED | F13: =Page1!F13 -> Country of Origin | I13: =Page1!I13 -> Country of Final Destination
A14: =Page1!A14 | B14: =Page1!B14 -> FITTINGS AND CORRUGATED BOXES | F14: =Page1!F14 -> INDIA | I14: =Page1!I14 -> AUSTRALIA
A15: =Page1!A15 | B15: =Page1!B15 -> 0
A16: =Page1!A16 -> Pre-Carraige by: | C16: =Page1!C16 -> Place of Receipt by Pre-Carraige | F16: Terms of Delivery: | H16: FOB MUMBAI
A17: =Page1!A17 | C17: =Page1!C17 -> 0
A18: =Page1!A18 -> Shipped per: | C18: =Page1!C18 -> Port of Loading: | F18: Terms of Payment: | H18: D.P.SIGHT DRAFT
A19: =Page1!A19 -> CAPE SYROS VOYAGE 092E | C19: =Page1!C19 -> NHAVA SHEVA-MUMBAI (INDIA)
A20: =Page1!A20 -> Port of Discharge: | C20: =Page1!C20 -> Port of destination | F20: Through: | H20: HDFC BANK LTD, GHATKOPAR (E) BRANCH
A21: =Page1!A21 -> FREMANTLE | C21: =Page1!C21 -> FREMANTLE | H21: GHATKOPAR (E), MUMBAI 400 077 (INDIA)
A22: Marks & Nos. | B22: No & Kinds of Pkgs Description of Goods | I22: Quantity | J22: Rate | K22: Amount
A23: =Page1!A23 -> GDW NOS : | B23: =Page1!B23 -> 421 PACKAGES (343 CARTONS & 78 HDP BUNDLES) CONTAINING | J23: =Page1!J23 -> FOB MUMBAI IN US$
A24: =Page1!A24 -> 2001 - 2421 | B24: =Page1!B24 -> PP EXTRUDED PIPES, PP & NYLON MOULDED FITTINGS & CORRUGATED BOXES
A25: =Page1!A25 -> 2421 | J25: =Page1!J25 -> 0 | K25: =Page1!K81 -> 13908.95
A26: =Page1!A26 -> 0 | B26: NYLON MOULDED FITTINGS
A27: =Page1!A27 -> 0 | B27: CODE | C27: SIZE (MM) | I27: PIECES | J27: PER 100 PCS
B28: GRC15 | C28: 15 | I28: 10000 | J28: 9.6 | K28: =I28*J28/100 -> 960
B29: GRC20 | C29: 20 | I29: 3000 | J29: 12 | K29: =I29*J29/100 -> 360
B30: GRC25 | C30: 25 | I30: 900 | J30: 15.6 | K30: =I30*J30/100 -> 140.4
A31: Container No. | B31: GRMFE25 | C31: 25 | I31: 1400 | J31: 33.6 | K31: =I31*J31/100 -> 470.4
A32: OOCU0793142 | B32: GRRS2015 | C32: 20*15 | I32: 1800 | J32: 21.6 | K32: =I32*J32/100 -> 388.8
B33: GRRS2520 | C33: 25*20 | I33: 1650 | J33: 24 | K33: =I33*J33/100 -> 396
B34: GRS25 | C34: 25 | I34: 500 | J34: 22.8 | K34: =I34*J34/100 -> 114
B35: GRT15 | C35: 15 | I35: 2160 | J35: 33.6 | K35: =I35*J35/100 -> 725.76
B36: GRT20 | C36: 20 | I36: 700 | J36: 40.8 | K36: =I36*J36/100 -> 285.6
B37: GRT25 | C37: 25 | I37: 1760 | J37: 50.4 | K37: =I37*J37/100 -> 887.04
B38: GRT32 | C38: 32 | I38: 1000 | J38: 91.2 | K38: =I38*J38/100 -> 912
B39: CORRUGATED BOXES
B40: CODE | C40: SIZE ( MM) | I40: PIECES | J40: PER PC
...
