Workbook

Sheet Moulded-2005
A1: 2005 INVOICE No: | F1: 05-06/2639
A2: DATE | F2: 23.12.2005
A3: Sr. No. | B3: CODE | C3: DESCRIPTION | D3: PACKING
D4: UNIT | E4: BOX | F4: PIECES | G4: BOXES
A6: 1 | B6: PP - 1501 | C6: 25 x 15MM Poly Riser | D6: 100 | E6: 2800
A7: 2 | B7: PP - 1502 | C7: 50X15 MM Poly Eriser
A8: 3 | B8: PP - 1503 | C8: 80 x 15MM Poly Riser | D8: 50 | E8: 1100
A9: 4 | B9: PP - 1504 | C9: 100 x 15MM Poly Riser. | D9: 50 | E9: 1000
A10: 5 | B10: PP - 1505 | C10: 125 X 15 MM Poly Riser
A11: 6 | B11: PP - 1506 | C11: 150 x 15MM Poly Riser. | D11: 50 | E11: 600
A12: 6A | B12: PH - 1506 | C12: 150x15 MM Poly Riser | D12: 50 | E12: 600
A13: 7 | B13: PP - 1508 | C13: 200 x 15MM Poly Riser. | D13: 10 | E13: 400
A14: 8 | B14: PP - 1509 | C14: 225 x 15MM Poly Riser. | D14: 10 | E14: 400
A15: 9 | B15: PP - 1512 | C15: Risers 1/2"(15MM)x12"(300MM) | D15: 10 | E15: 300 | F15: 100000 | G15: 334
A16: 9A | B16: PH - 1512 | C16: 300 x 15MM Ply Riser. | D16: 10 | E16: 300 | G16: =F16/E16 -> 0
A17: 10 | B17: PPA - 1506 | C17: 150 x 15MM Articulated P.Riser. | D17: 10 | E17: 130 | G17: =F17/E17 -> 0
A18: 11 | B18: PPA - 1508 | C18: 200 x 15MM Articulated P.Riser | D18: 10 | E18: 110 | G18: =F18/E18 -> 0
A19: 12 | B19: PPA - 1512 | C19: Articulated Riser 1/2"(15mm)x300MM | D19: 10 | E19: 80 | F19: 5040 | G19: =F19/E19 -> 63
A20: 13 | B20: FFC - 15 | C20: F/F Couplings 1/2"(15MM) | D20: 100 | E20: 1200 | F20: 150000 | G20: =F20/E20 -> 125
A21: 14 | B21: MFE - 15 | C21: M/F Elbow 1/2" (15MM) | D21: 100 | E21: 1000 | F21: 58400 | G21: 59
A22: 15 | B22: CAP - 15 | C22: 15MM F.I.Cap. | D22: 50 | E22: 2800 | G22: =F22/E22 -> 0
A23: 16 | B23: CUTPL - 15 | C23: 15MM Rigid Cut Off Riser. | D23: 50 | E23: 550 | G23: =F23/E23 -> 0
A24: 17 | B24: PP - 2008 | C24: 200 x 20MM Poly Riser. | D24: 10 | E24: 330 | G24: =F24/E24 -> 0
A25: 18 | B25: PP/PH - 2010 | C25: Riser 240x20MM Spacer Meter | D25: 10 | E25: 270 | G25: =F25/E25 -> 0
A26: 18A | B26: 90447000 | C26: Philmac spacer Meter 20 x 240 | D26: 10 | E26: 270 | G26: =F26/E26 -> 0
A27: 19 | B27: PP - 2012 | C27: 300 x 20MM Poly Riser. | D27: 10 | E27: 230 | G27: =F27/E27 -> 0
A28: 19A | B28: 90442300 | C28: Philmac 300 x 20MM Riser | D28: 10 | E28: 230 | G28: =F28/E28 -> 0
A29: 20 | B29: PPA - 2008 | C29: 200 x 20MM Artic Riser. | D29: 5 | E29: 75 | G29: =F29/E29 -> 0
A30: 21 | B30: PPA - 2012 | C30: 300 x 20MM Artic Riser | D30: 5 | E30: 50 | G30: =F30/E30 -> 0
A31: 22 | B31: MFE - 20 | C31: M/F Elbow 20MM | D31: 50 | E31: 600 | G31: =F31/E31 -> 0
A32: 23 | B32: MJC - 18 | C32: 15MM x 1/8" Micro Spray cap | D32: 50 | E32: 2000 | G32: =F32/E32 -> 0
A33: 24 | B33: SPASTO | C33: Shrub Adaptor Toro Head | D33: 100 | E33: 2000 | G33: =F33/E33 -> 0
A34: 25 | B34: MFA - 15 | C34: 15MM M/F Adaptors. | D34: 50 | E34: 1750 | G34: =F34/E34 -> 0
A35: 26 | B35: SMFE - 15 | C35: M/F Elbow | D35: 50 | E35: 800 | G35: =F35/E35 -> 0
D36: TOTAL | F36: =SUM(F6:F35) -> 313440 | G36: =SUM(G15:G35) -> 581

Sheet Moulded-2006
A1: 2006 INVOICE No: | F1: 05-06/2649 | G1: 06-07/2685 | H1: TOTAL
A2: DATE | F2: 23.03.2006 | G2: 28.12.2006
A3: Sr. No. | B3: CODE | C3: DESCRIPTION | D3: PACKING
D4: UNIT | E4: BOX | F4: PIECES | G4: PIECES | H4: PIECES | I4: BOXES
A6: 1 | B6: PP - 1501 | C6: 25 x 15MM Poly Riser | D6: 100 | E6: 2800 | G6: 11200 | H6: =SUM(F6:G6) -> 11200 | I6: =H6/E6 -> 4
A7: 2 | B7: PP - 1502 | C7: 50X15 MM Poly Eriser | D7: 100 | E7: 2500 | H7: =SUM(F7:G7) -> 0 | I7: =H7/E7 -> 0
A8: 3 | B8: PP - 1503 | C8: 80 x 15MM Poly Riser | D8: 50 | E8: 1100 | F8: 44000 | H8: =SUM(F8:G8) -> 44000 | I8: =H8/E8 -> 40
A9: 4 | B9: PP - 1504 | C9: 100 x 15MM Poly Riser. | D9: 50 | E9: 1000 | F9: 32000 | G9: 3600 | H9: =SUM(F9:G9) -> 35600 | I9: 36
A10: 5 | B10: PP - 1505 | C10: 125 X 15 MM Poly Riser | D10: 50 | E10: 800 | H10: =SUM(F10:G10) -> 0 | I10: =H10/E10 -> 0
A11: 6 | B11: PP - 1506 | C11: 150 x 15MM Poly Riser. | D11: 50 | E11: 600 | F11: 48000 | H11: =SUM(F11:G11) -> 48000 | I11: =H11/E11 -> 80
A12: 6A | B12: PH - 1506 | C12: 150x15 MM Poly Riser | D12: 50 | E12: 600 | H12: =SUM(F12:G12) -> 0 | I12: =H12/E12 -> 0
A13: 7 | B13: PP - 1508 | C13: 200 x 15MM Poly Riser. | D13: 10 | E13: 400 | F13: 19200 | G13: 9200 | H13: =SUM(F13:G13) -> 28400 | I13: =H13/E13 -> 71
A14: 8 | B14: PP - 1509 | C14: 225 x 15MM Poly Riser. | D14: 10 | E14: 400 | F14: 34400 | G14: 40000 | H14: =SUM(F14:G14) -> 74400 | I14: =H14/E14 -> 186
A15: 9 | B15: PP - 1512 | C15: Risers 1/2"(15MM)x12"(300MM) | D15: 10 | E15: 300 | G15: 60500 | H15: =SUM(F15:G15) -> 60500 | I15: 202
A16: 9A | B16: PH - 1512 | C16: 300 x 15MM Ply Riser. | D16: 10 | E16: 300 | H16: =SUM(F16:G16) -> 0 | I16: =H16/E16 -> 0
A17: 10 | B17: PPA - 1506 | C17: 150 x 15MM Articulated P.Riser. | D17: 10 | E17: 130 | F17: 5070 | H17: =SUM(F17:G17) -> 5070 | I17: =H17/E17 -> 39
A18: 11 | B18: PPA - 1508 | C18: 200 x 15MM Articulated P.Riser | D18: 10 | E18: 110 | F18: 18040 | H18: =SUM(F18:G18) -> 18040 | I18: =H18/E18 -> 164
A19: 12 | B19: PPA - 1512 | C19: Articulated Riser 1/2"(15mm)x300MM | D19: 10 | E19: 80 | G19: 6400 | H19: =SUM(F19:G19) -> 6400 | I19: =H19/E19 -> 80
A20: 13 | B20: FFC - 15 | C20: F/F Couplings 1/2"(15MM) | D20: 100 | E20: 1200 | G20: 54000 | H20: =SUM(F20:G20) -> 54000 | I20: =H20/E20 -> 45
A21: 14 | B21: MFE - 15 | C21: M/F Elbow 1/2" (15MM) | D21: 100 | E21: 1000 | H21: =SUM(F21:G21) -> 0 | I21: =H21/E21 -> 0
A22: 15 | B22: CAP - 15 | C22: 15MM F.I.Cap. | D22: 50 | E22: 2800 | G22: 5600 | H22: =SUM(F22:G22) -> 5600 | I22: =H22/E22 -> 2
A23: 16 | B23: CUTPL - 15 | C23: 15MM Rigid Cut Off Riser. | D23: 50 | E23: 550 | H23: =SUM(F23:G23) -> 0 | I23: =H23/E23 -> 0
A24: 17 | B24: PP - 2008 | C24: 200 x 20MM Poly Riser. | D24: 10 | E24: 330 | H24: =SUM(F24:G24) -> 0 | I24: =H24/E24 -> 0
A25: 18 | B25: PP/PH - 2010 | C25: Riser 240x20MM Spacer Meter | D25: 10 | E25: 270 | H25: =SUM(F25:G25) -> 0 | I25: =H25/E25 -> 0
A26: 18A | B26: 90447000 | C26: Philmac spacer Meter 20 x 240 | D26: 10 | E26: 270 | H26: =SUM(F26:G26) -> 0 | I26: =H26/E26 -> 0
A27: 19 | B27: PP - 2012 | C27: 300 x 20MM Poly Riser. | D27: 10 | E27: 230 | H27: =SUM(F27:G27) -> 0 | I27: =H27/E27 -> 0
A28: 19A | B28: 90442300 | C28: Philmac 300 x 20MM Riser | D28: 10 | E28: 230 | H28: =SUM(F28:G28) -> 0 | I28: =H28/E28 -> 0
A29: 20 | B29: PPA - 2008 | C29: 200 x 20MM Artic Riser. | D29: 5 | E29: 75 | H29: =SUM(F29:G29) -> 0 | I29: =H29/E29 -> 0
A30: 21 | B30: PPA - 2012 | C30: 300 x 20MM Artic Riser | D30: 5 | E30: 50 | H30: =SUM(F30:G30) -> 0 | I30: =H30/E30 -> 0
A31: 22 | B31: MFE - 20 | C31: M/F Elbow 20MM | D31: 50 | E31: 600 | H31: =SUM(F31:G31) -> 0 | I31: =H31/E31 -> 0
A32: 23 | B32: MJC - 18 | C32: 15MM x 1/8" Micro Spray cap | D32: 50 | E32: 2000 | H32: =SUM(F32:G32) -> 0 | I32: =H32/E32 -> 0
A33: 24 | B33: SPASTO | C33: Shrub Adaptor Toro Head | D33: 100 | E33: 2000 | H33: =SUM(F33:G33) -> 0 | I33: =H33/E33 -> 0
A34: 25 | B34: MFA - 15 | C34: 15MM M/F Adaptors. | D34: 50 | E34: 1750 | H34: =SUM(F34:G34) -> 0 | I34: =H34/E34 -> 0
A35: 26 | B35: SMFE - 15 | C35: M/F Elbow | D35: 50 | E35: 800 | H35: =SUM(F35:G35) -> 0 | I35: =H35/E35 -> 0
D36: TOTAL | F36: =SUM(F6:F35) -> 200710 | G36: =SUM(G6:G35) -> 190500 | H36: =SUM(H6:H35) -> 391210 | I36: =SUM(I6:I35) -> 949

Sheet Moulded-2007
A1: 2007 INVOICE No: | F1: 06-07/2687 | G1: 07-08/2706 | H1: 07-08/2707 | I1: 07-08/2717 | J1: 07-08/2723 | K1: 07-08/2734A | L1: TOTAL
A2: DATE | F2: 24.01.2007 | G2: 23.04.2007 | H2: 24.04.2007 | I2: 29.06.2007 | J2: 22.08.2007 | K2: 29.10.2007 | L2: L
A3: Sr. No. | B3: CODE | C3: DESCRIPTION | D3: PACKING
D4: UNIT | E4: BOX | F4: PIECES | G4: PIECES | H4: PIECES | I4: PIECES | J4: PIECES | K4: PIECES | L4: PIECES | M4: BOXES
A6: 1 | B6: PP - 1501 | C6: 25 x 15MM Poly Riser | D6: 100 | E6: 2800 | F6: 100800 | G6: 78400 | J6: 50400 | K6: 36400 | L6: =SUM(F6:K6) -> 266000 | M6: =L6/E6 -> 95
A7: 2 | B7: PP - 1502 | C7: 50X15 MM Poly Eriser | D7: 50 | E7: 2500 | L7: =SUM(F7:K7) -> 0 | M7: =L7/E7 -> 0
A8: 3 | B8: PP - 1503 | C8: 80 x 15MM Poly Riser | D8: 50 | E8: 1100 | F8: 19800 | G8: 29700 | K8: 19800 | L8: =SUM(F8:K8) -> 69300 | M8: =L8/E8 -> 63
A9: 4 | B9: PP - 1504 | C9: 100 x 15MM Poly Riser. | D9: 50 | E9: 1000 | F9: 19800 | G9: 16000 | K9: 23000 | L9: =SUM(F9:K9) -> 58800 | M9: 59
A10: 5 | B10: PP - 1505 | C10: 125 X 15 MM Poly Riser | D10: 50 | E10: 800 | L10: =SUM(F10:K10) -> 0 | M10: =L10/E10 -> 0
A11: 6 | B11: PP - 1506 | C11: 150 x 15MM Poly Riser. | D11: 50 | E11: 600 | F11: 17400 | G11: 24000 | K11: 30000 | L11: =SUM(F11:K11) -> 71400 | M11: =L11/E11 -> 119
A12: 6A | B12: PH - 1506 | C12: 150x15 MM Poly Riser | D12: 50 | E12: 600 | F12: 9000 | L12: =SUM(F12:K12) -> 9000 | M12: =L12/E12 -> 15
A13: 7 | B13: PP - 1508 | C13: 200 x 15MM Poly Riser. | D13: 10 | E13: 400 | G13: 10000 | K13: 12000 | L13: =SUM(F13:K13) -> 22000 | M13: =L13/E13 -> 55
A14: 8 | B14: PP - 1509 | C14: 225 x 15MM Poly Riser. | D14: 10 | E14: 400 | G14: 20000 | L14: =SUM(F14:K14) -> 20000 | M14: =L14/E14 -> 50
A15: 9 | B15: PP - 1512 | C15: Risers 1/2"(15MM)x12"(300MM) | D15: 10 | E15: 300 | F15: 9500 | G15: 33000 | L15: =SUM(F15:K15) -> 42500 | M15: 142
A16: 9A | B16: PH - 1512 | C16: 300 x 15MM Ply Riser. | D16: 10 | E16: 300 | F16: 16000 | L16: =SUM(F16:K16) -> 16000 | M16: 54
A17: 10 | B17: PPA - 1506 | C17: 150 x 15MM Articulated P.Riser. | D17: 10 | E17: 130 | F17: 5200 | K17: 2990 | L17: =SUM(F17:K17) -> 8190 | M17: =L17/E17 -> 63
A18: 11 | B18: PPA - 1508 | C18: 200 x 15MM Articulated P.Riser | D18: 10 | E18: 110 | G18: 4950 | K18: 6050 | L18: =SUM(F18:K18) -> 11000 | M18: =L18/E18 -> 100
A19: 12 | B19: PPA - 1512 | C19: Articulated Riser 1/2"(15mm)x300MM | D19: 10 | E19: 80 | F19: 7200 | G19: 5840 | K19: 11840 | L19: =SUM(F19:K19) -> 24880 | M19: =L19/E19 -> 311
A20: 13 | B20: FFC - 15 | C20: F/F Couplings 1/2"(15MM) | D20: 100 | E20: 1200 | F20: 54000 | G20: 97200 | L20: =SUM(F20:K20) -> 151200 | M20: =L20/E20 -> 126
A21: 14 | B21: MFE - 15 | C21: M/F Elbow 1/2" (15MM) | D21: 100 | E21: 1000 | F21: 45000 | L21: =SUM(F21:K21) -> 45000 | M21: =L21/E21 -> 45
A22: 15 | B22: CAP - 15 | C22: 15MM F.I.Cap. | D22: 50 | E22: 2800 | F22: 22400 | G22: 14000 | L22: =SUM(F22:K22) -> 36400 | M22: =L22/E22 -> 13
A23: 16 | B23: CUTPL - 15 | C23: 15MM Rigid Cut Off Riser. | D23: 50 | E23: 550 | F23: 27500 | L23: =SUM(F23:K23) -> 27500 | M23: =L23/E23 -> 50
A24: 17 | B24: PP - 2008 | C24: 200 x 20MM Poly Riser. | D24: 10 | E24: 330 | J24: 2640 | L24: =SUM(F24:K24) -> 2640 | M24: =L24/E24 -> 8
A25: 18 | B25: PP/PH - 2010 | C25: Riser 240x20MM Spacer Meter | D25: 10 | E25: 270 | H25: 9990 | I25: 9990 | L25: =SUM(F25:K25) -> 19980 | M25: =L25/E25 -> 74
A26: 18A | B26: 90447000 | C26: Philmac spacer Meter 20 x 240 | D26: 10 | E26: 270 | J26: 19710 | L26: =SUM(F26:K26) -> 19710 | M26: =L26/E26 -> 73
A27: 19 | B27: PP - 2012 | C27: 300 x 20MM Poly Riser. | D27: 10 | E27: 230 | J27: 9660 | L27: =SUM(F27:K27) -> 9660 | M27: =L27/E27 -> 42
A28: 19A | B28: 90442300 | C28: Philmac 300 x 20MM Riser | D28: 10 | E28: 230 | J28: 10120 | L28: =SUM(F28:K28) -> 10120 | M28: =L28/E28 -> 44
A29: 20 | B29: PPA - 2008 | C29: 200 x 20MM Artic Riser. | D29: 5 | E29: 75 | J29: 3000 | K29: 3000 | L29: =SUM(F29:K29) -> 6000 | M29: =L29/E29 -> 80
A30: 21 | B30: PPA - 2012 | C30: 300 x 20MM Artic Riser | D30: 5 | E30: 50 | J30: 9400 | K30: 5000 | L30: =SUM(F30:K30) -> 14400 | M30: =L30/E30 -> 288
A31: 22 | B31: MFE - 20 | C31: M/F Elbow 20MM | D31: 50 | E31: 600 | J31: 28200 | L31: =SUM(F31:K31) -> 28200 | M31: =L31/E31 -> 47
A32: 23 | B32: MJC - 18 | C32: 15MM x 1/8" Micro Spray cap | D32: 50 | E32: 2000 | J32: 16000 | L32: =SUM(F32:K32) -> 16000 | M32: =L32/E32 -> 8
A33: 24 | B33: SPASTO | C33: Shrub Adaptor Toro Head | D33: 100 | E33: 2000 | J33: 18000 | L33: =SUM(F33:K33) -> 18000 | M33: =L33/E33 -> 9
A34: 25 | B34: MFA - 15 | C34: 15MM M/F Adaptors. | D34: 50 | E34: 1750 | J34: 40250 | L34: =SUM(F34:K34) -> 40250 | M34: =L34/E34 -> 23
A35: 26 | B35: SMFE - 15 | C35: M/F Elbow | D35: 50 | E35: 800 | L35: =SUM(F35:K35) -> 0 | M35: =L35/E35 -> 0
D36: TOTAL | F36: =SUM(F6:F35) -> 353600 | G36: =SUM(G6:G35) -> 333090 | H36: =SUM(H6:H35) -> 9990 | I36: =SUM(I6:I35) -> 9990 | J36: =SUM(J6:J35) -> 207380 | K36: =SUM(K6:K35) -> 150080 | L36: =SUM(L6:L35) -> 1064130 | M36: =SUM(M6:M35) -> 2056

Sheet Moulded-2008
A1: 2008 INVOICE No: | F1: 07-08/2741 | G1: 07-08/2768 | H1: 08-09/2774 | I1: 08-09/2779 | J1: 08-09/2781 | K1: TOTAL
A2: DATE | F2: 08.02.2008 | G2: 24.09.2008 | H2: 20.10.2008 | I2: 24.11.2008 | J2: 19.12.2008
A3: Sr. No. | B3: CODE | C3: DESCRIPTION | D3: PACKING
D4: UNIT | E4: BOX | F4: PIECES | G4: PIECES | H4: PIECES | I4: PIECES | J4: PIECES | K4: PIECES | L4: BOXES
A6: 1 | B6: PP - 1501 | C6: 25 x 15MM Poly Riser | D6: 100 | E6: 2800 | F6: 112000 | G6: 50400 | K6: =SUM(F6:J6) -> 162400 | L6: =K6/E6 -> 58
A7: 2 | B7: PP - 1502 | C7: 50X15 MM Poly Eriser | D7: 50 | E7: 2800 | K7: =SUM(F7:J7) -> 0 | L7: =K7/E7 -> 0
A8: 3 | B8: PP - 1503 | C8: 80 x 15MM Poly Riser | D8: 50 | E8: 1100 | G8: 19800 | I8: 17600 | K8: =SUM(F8:J8) -> 37400 | L8: =K8/E8 -> 34
A9: 4 | B9: PP - 1504 | C9: 100 x 15MM Poly Riser. | D9: 50 | E9: 1000 | F9: 1000 | G9: 10000 | I9: 10000 | K9: =SUM(F9:J9) -> 21000 | L9: =K9/E9 -> 21
A10: 5 | B10: PP - 1505 | C10: 125 X 15 MM Poly Riser | D10: 50 | E10: 800 | K10: =SUM(F10:J10) -> 0 | L10: =K10/E10 -> 0
A11: 6 | B11: PP - 1506 | C11: 150 x 15MM Poly Riser. | D11: 50 | E11: 600 | G11: 20400 | H11: 7800 | I11: 7200 | K11: =SUM(F11:J11) -> 35400 | L11: =K11/E11 -> 59
A12: 6A | B12: PH - 1506 | C12: 150x15 MM Poly Riser | D12: 50 | E12: 600 | K12: =SUM(F12:J12) -> 0 | L12: =K12/E12 -> 0
A13: 7 | B13: PP - 1508 | C13: 200 x 15MM Poly Riser. | D13: 10 | E13: 400 | G13: 10000 | H13: 8000 | K13: =SUM(F13:J13) -> 18000 | L13: =K13/E13 -> 45
A14: 8 | B14: PP - 1509 | C14: 225 x 15MM Poly Riser. | D14: 10 | E14: 400 | H14: 20400 | K14: =SUM(F14:J14) -> 20400 | L14: =K14/E14 -> 51
A15: 9 | B15: PP - 1512 | C15: Risers 1/2"(15MM)x12"(300MM) | D15: 10 | E15: 300 | K15: =SUM(F15:J15) -> 0 | L15: =K15/E15 -> 0
A16: 9A | B16: PH - 1512 | C16: 300 x 15MM Ply Riser. | D16: 10 | E16: 300 | K16: =SUM(F16:J16) -> 0 | L16: =K16/E16 -> 0
A17: 10 | B17: PPA - 1506 | C17: 150 x 15MM Articulated P.Riser. | D17: 10 | E17: 130 | G17: 2080 | K17: =SUM(F17:J17) -> 2080 | L17: =K17/E17 -> 16
A18: 11 | B18: PPA - 1508 | C18: 200 x 15MM Articulated P.Riser | D18: 10 | E18: 110 | G18: 3080 | K18: =SUM(F18:J18) -> 3080 | L18: =K18/E18 -> 28
A19: 12 | B19: PPA - 1512 | C19: Articulated Riser 1/2"(15mm)x300MM | D19: 10 | E19: 80 | F19: 13200 | G19: 5040 | K19: =SUM(F19:J19) -> 18240 | L19: =K19/E19 -> 228
A20: 13 | B20: FFC - 15 | C20: F/F Couplings 1/2"(15MM) | D20: 100 | E20: 1200 | F20: 57600 | G20: 20400 | I20: 70800 | K20: =SUM(F20:J20) -> 148800 | L20: =K20/E20 -> 124
A21: 14 | B21: MFE - 15 | C21: M/F Elbow 1/2" (15MM) | D21: 100 | E21: 1000 | F21: 20000 | G21: 10000 | J21: 14400 | K21: =SUM(F21:J21) -> 44400 | L21: 45
A22: 15 | B22: CAP - 15 | C22: 15MM F.I.Cap. | D22: 50 | E22: 2800 | F22: 16800 | G22: 5600 | I22: 22400 | J22: 11200 | K22: =SUM(F22:J22) -> 56000 | L22: =K22/E22 -> 20
A23: 16 | B23: CUTPL - 15 | C23: 15MM Rigid Cut Off Riser. | D23: 50 | E23: 550 | F23: 14850 | G23: 4950 | I23: 14850 | K23: =SUM(F23:J23) -> 34650 | L23: =K23/E23 -> 63
A24: 17 | B24: PP - 2008 | C24: 200 x 20MM Poly Riser. | D24: 10 | E24: 330 | K24: =SUM(F24:J24) -> 0 | L24: =K24/E24 -> 0
A25: 18 | B25: PP/PH - 2010 | C25: Riser 240x20MM Spacer Meter | D25: 10 | E25: 270 | H25: 5130 | K25: =SUM(F25:J25) -> 5130 | L25: =K25/E25 -> 19
A26: 18A | B26: 90447000 | C26: Philmac spacer Meter 20 x 240 | D26: 10 | E26: 270 | K26: =SUM(F26:J26) -> 0 | L26: =K26/E26 -> 0
A27: 19 | B27: PP - 2012 | C27: 300 x 20MM Poly Riser. | D27: 10 | E27: 230 | G27: 2070 | H27: 5750 | K27: =SUM(F27:J27) -> 7820 | L27: =K27/E27 -> 34
A28: 19A | B28: 90442300 | C28: Philmac 300 x 20MM Riser | D28: 10 | E28: 230 | K28: =SUM(F28:J28) -> 0 | L28: =K28/E28 -> 0
A29: 20 | B29: PPA - 2008 | C29: 200 x 20MM Artic Riser. | D29: 5 | E29: 75 | K29: =SUM(F29:J29) -> 0 | L29: =K29/E29 -> 0
A30: 21 | B30: PPA - 2012 | C30: 300 x 20MM Artic Riser | D30: 5 | E30: 50 | G30: 3000 | H30: 3000 | K30: =SUM(F30:J30) -> 6000 | L30: =K30/E30 -> 120
A31: 22 | B31: MFE - 20 | C31: M/F Elbow 20MM | D31: 50 | E31: 600 | K31: =SUM(F31:J31) -> 0 | L31: =K31/E31 -> 0
A32: 23 | B32: MJC - 18 | C32: 15MM x 1/8" Micro Spray cap | D32: 50 | E32: 2000 | J32: 16000 | K32: =SUM(F32:J32) -> 16000 | L32: =K32/E32 -> 8
A33: 24 | B33: SPASTO | C33: Shrub Adaptor Toro Head | D33: 100 | E33: 2000 | J33: 16000 | K33: =SUM(F33:J33) -> 16000 | L33: =K33/E33 -> 8
A34: 25 | B34: MFA - 15 | C34: 15MM M/F Adaptors. | D34: 50 | E34: 1750 | G34: 17500 | I34: 10500 | J34: 8750 | K34: =SUM(F34:J34) -> 36750 | L34: =K34/E34 -> 21
D35: TOTAL | F35: =SUM(F6:F34) -> 235450 | G35: =SUM(G6:G34) -> 184320 | H35: =SUM(H6:H34) -> 50080 | I35: =SUM(I6:I34) -> 153350 | J35: =SUM(J6:J34) -> 66350 | K35: =SUM(K6:K34) -> 689550 | L35: =SUM(L6:L34) -> 1002

Sheet Moulded-2009
A1: 2009 INVOICE No: | F1: 09-10/2805 | G1: 09-10/2815 | H1: 09-10/2819 | I1: 09-10/2822 | J1: 09-10/2828 | K1: 09-10/2833 | L1: 09-10/2836 | M1: TOTAL
A2: DATE | F2: 11.06.2009 | G2: 04.08.2009 | H2: 28.08.2009 | I2: 21.09.2009 | J2: 28.10.2009 | K2: 01.12.2009 | L2: 21.12.2009
A3: Sr. No. | B3: CODE | C3: DESCRIPTION | D3: PACKING
D4: UNIT | E4: BOX | F4: PIECES | G4: PIECES | H4: PIECES | I4: PIECES | J4: PIECES | K4: PIECES | L4: PIECES | M4: PIECES | N4: BOXES
A6: 1 | B6: PP - 1501 | C6: 25 x 15MM Poly Riser | D6: 100 | E6: 2800 | M6: =SUM(F6:L6) -> 0 | N6: =M6/E6 -> 0
A7: 2 | B7: PP - 1502 | C7: 50X15 MM Poly Eriser | D7: 100 | E7: 2800 | M7: =SUM(F7:L7) -> 0 | N7: =M7/E7 -> 0
A8: 3 | B8: PP - 1503 | C8: 80 x 15MM Poly Riser | D8: 50 | E8: 1100 | F8: 5500 | G8: 15400 | H8: 6600 | I8: 3300 | K8: 4400 | L8: 9900 | M8: =SUM(F8:L8) -> 45100 | N8: =M8/E8 -> 41
A9: 4 | B9: PP - 1504 | C9: 100 x 15MM Poly Riser. | D9: 50 | E9: 1000 | F9: 10000 | G9: 10000 | H9: 5000 | K9: 22000 | M9: =SUM(F9:L9) -> 47000 | N9: =M9/E9 -> 47
A10: 5 | B10: PP - 1505 | C10: 125 X 15 MM Poly Riser | D10: 50 | E10: 800 | M10: =SUM(F10:L10) -> 0 | N10: =M10/E10 -> 0
A11: 6 | B11: PP - 1506 | C11: 150 x 15MM Poly Riser. | D11: 50 | E11: 600 | F11: 10200 | G11: 12600 | I11: 5400 | M11: =SUM(F11:L11) -> 28200 | N11: =M11/E11 -> 47
A12: 6A | B12: PH - 1506 | C12: 150x15 MM Poly Riser | D12: 50 | E12: 600 | F12: 4800 | M12: =SUM(F12:L12) -> 4800 | N12: =M12/E12 -> 8
A13: 7 | B13: PP - 1508 | C13: 200 x 15MM Poly Riser. | D13: 10 | E13: 400 | M13: =SUM(F13:L13) -> 0 | N13: =M13/E13 -> 0
A14: 8 | B14: PP - 1509 | C14: 225 x 15MM Poly Riser. | D14: 10 | E14: 400 | F14: 10000 | G14: 6000 | H14: 12000 | I14: 3600 | J14: 1600 | K14: 2000 | L14: 7200 | M14: =SUM(F14:L14) -> 42400 | N14: =M14/E14 -> 106
A15: 9 | B15: PP - 1512 | C15: Risers 1/2"(15MM)x12"(300MM) | D15: 10 | E15: 300 | M15: =SUM(F15:L15) -> 0 | N15: =M15/E15 -> 0
A16: 9A | B16: PH - 1512 | C16: 300 x 15MM Ply Riser. | D16: 10 | E16: 300 | M16: =SUM(F16:L16) -> 0 | N16: =M16/E16 -> 0
A17: 10 | B17: PPA - 1506 | C17: 150 x 15MM Articulated P.Riser. | D17: 10 | E17: 130 | I17: 1950 | M17: =SUM(F17:L17) -> 1950 | N17: =M17/E17 -> 15
A18: 11 | B18: PPA - 1508 | C18: 200 x 15MM Articulated P.Riser | D18: 10 | E18: 110 | F18: 2970 | H18: 3630 | I18: 1430 | L18: 2750 | M18: =SUM(F18:L18) -> 10780 | N18: =M18/E18 -> 98
A19: 12 | B19: PPA - 1512 | C19: Articulated Riser 1/2"(15mm)x300MM | D19: 10 | E19: 80 | M19: =SUM(F19:L19) -> 0 | N19: =M19/E19 -> 0
A20: 13 | B20: FFC - 15 | C20: F/F Couplings 1/2"(15MM) | D20: 100 | E20: 1200 | F20: 9600 | G20: 50400 | H20: 16800 | I20: 27600 | J20: 6000 | K20: 14400 | L20: 18000 | M20: =SUM(F20:L20) -> 142800 | N20: =M20/E20 -> 119
A21: 14 | B21: MFE - 15 | C21: M/F Elbow 1/2" (15MM) | D21: 100 | E21: 1000 | G21: 12000 | I21: 10000 | M21: =SUM(F21:L21) -> 22000 | N21: =M21/E21 -> 22
A22: 15 | B22: CAP - 15 | C22: 15MM F.I.Cap. | D22: 50 | E22: 2800 | G22: 11200 | I22: 14000 | K22: 5600 | M22: =SUM(F22:L22) -> 30800 | N22: =M22/E22 -> 11
A23: 16 | B23: CUTPL - 15 | C23: 15MM Rigid Cut Off Riser. | D23: 50 | E23: 550 | F23: 5500 | G23: 4950 | H23: 2200 | I23: 3300 | K23: 16500 | M23: =SUM(F23:L23) -> 32450 | N23: =M23/E23 -> 59
A24: 17 | B24: PP - 2008 | C24: 200 x 20MM Poly Riser. | D24: 10 | E24: 330 | M24: =SUM(F24:L24) -> 0 | N24: =M24/E24 -> 0
A25: 18 | B25: PP - 2010 | C25: Riser 240x20MM Spacer Meter | D25: 10 | E25: 270 | M25: =SUM(F25:L25) -> 0 | N25: =M25/E25 -> 0
A26: 18A | B26: 90447000 | C26: Philmac spacer Meter 20 x 240 | D26: 10 | E26: 270 | F26: 5400 | G26: 4590 | M26: =SUM(F26:L26) -> 9990 | N26: =M26/E26 -> 37
A27: 19 | B27: PP - 2012 | C27: 300 x 20MM Poly Riser. | D27: 10 | E27: 230 | H27: 2990 | M27: =SUM(F27:L27) -> 2990 | N27: =M27/E27 -> 13
A28: 19A | B28: 90442300 | C28: Philmac 300 x 20MM Riser | D28: 10 | E28: 230 | M28: =SUM(F28:L28) -> 0 | N28: =M28/E28 -> 0
A29: 20 | B29: PPA - 2008 | C29: 200 x 20MM Artic Riser. | D29: 5 | E29: 75 | K29: 3000 | M29: =SUM(F29:L29) -> 3000 | N29: =M29/E29 -> 40
A30: 21 | B30: PPA - 2012 | C30: 300 x 20MM Artic Riser | D30: 5 | E30: 50 | H30: 750 | I30: 1250 | J30: 1500 | M30: =SUM(F30:L30) -> 3500 | N30: =M30/E30 -> 70
A31: 22 | B31: MFE - 20 | C31: M/F Elbow 20MM | D31: 50 | E31: 600 | M31: =SUM(F31:L31) -> 0 | N31: =M31/E31 -> 0
A32: 23 | B32: MJC - 18 | C32: 15MM x 1/8" Micro Spray cap | D32: 50 | E32: 2000 | M32: =SUM(F32:L32) -> 0 | N32: =M32/E32 -> 0
A33: 24 | B33: SPASTO | C33: Shrub Adaptor Toro Head | D33: 100 | E33: 2000 | M33: =SUM(F33:L33) -> 0 | N33: =M33/E33 -> 0
A34: 25 | B34: MFA - 15 | C34: 15MM M/F Adaptors. | D34: 50 | E34: 1750 | G34: 10500 | I34: 10500 | M34: =SUM(F34:L34) -> 21000 | N34: =M34/E34 -> 12
D35: TOTAL | F35: =SUM(F6:F34) -> 63970 | G35: =SUM(G6:G34) -> 137640 | H35: =SUM(H6:H34) -> 49970 | I35: =SUM(I6:I34) -> 82330 | J35: =SUM(J6:J34) -> 9100 | K35: =SUM(K6:K34) -> 67900 | L35: =SUM(L6:L34) -> 37850 | M35: =SUM(M6:M34) -> 448760 | N35: =SUM(N6:N34) -> 745

Sheet Moulded-2010
A1: 2010 INVOICE No: | F1: 09-10/2839 | G1: 345774 | H1: 09-10/2850 | I1: 348362 | J1: 349823 | K1: 351649 | L1: 352745 | M1: 354571 | N1: 355302 | O1: 355667 | P1: 356032 | Q1: 356397 | R1: 357128
A2: DATE | F2: 11.01.2010 | G2: 10.02.2010 | H2: 26.03.2010 | I2: 24.6.2010 | J2: 04.8.2010 | K2: 7.9.2010 | L2: 28.9.2010 | M2: 13.10.2010 | N2: 18.10.2010 | O2: 10.11.2010 | P2: 17./11.2010 | Q2: 24.11.2010 | R2: 22.12.2010
A3: Sr. No. | B3: CODE | C3: DESCRIPTION | D3: PACKING | S3: TOTAL
D4: UNIT | E4: BOX | F4: PIECES | G4: PIECES | H4: PIECES | I4: PIECES | J4: PIECES | K4: PIECES | L4: PIECES | M4: PIECES | N4: PIECES | O4: PIECES | P4: PIECES | Q4: PIECES | R4: PIECES | S4: PIECES | T4: BOXES
A6: 1 | B6: PP - 1501 | C6: 25 x 15MM Poly Riser | D6: 100 | E6: 2800 | S6: =SUM(F6:R6) -> 0 | T6: =S6/E6 -> 0
A7: 2 | B7: PP - 1502 | C7: 50X15 MM Poly Eriser | D7: 100 | E7: 2800 | S7: =SUM(F7:R7) -> 0 | T7: =S7/E7 -> 0
A8: 3 | B8: PP - 1503 | C8: 80 x 15MM Poly Riser | D8: 50 | E8: 1100 | F8: 29700 | L8: 9900 | Q8: 11000 | S8: =SUM(F8:R8) -> 50600 | T8: =S8/E8 -> 46
A9: 4 | B9: PP - 1504 | C9: 100 x 15MM Poly Riser. | D9: 50 | E9: 1000 | F9: 9000 | K9: 15000 | Q9: 11000 | R9: 6000 | S9: =SUM(F9:R9) -> 41000 | T9: =S9/E9 -> 41
A10: 5 | B10: PP - 1505 | C10: 125 X 15 MM Poly Riser | D10: 50 | E10: 800 | L10: 4000 | M10: 12800 | Q10: 3200 | R10: 2400 | S10: =SUM(F10:R10) -> 22400 | T10: =S10/E10 -> 28
A11: 6 | B11: PP - 1506 | C11: 150 x 15MM Poly Riser. | D11: 50 | E11: 600 | H11: 27000 | I11: 9000 | S11: =SUM(F11:R11) -> 36000 | T11: =S11/E11 -> 60
A12: 6A | B12: PH - 1506 | C12: 150x15 MM Poly Riser | D12: 50 | E12: 600 | I12: 5400 | Q12: 3600 | R12: 1200 | S12: =SUM(F12:R12) -> 10200 | T12: =S12/E12 -> 17
A13: 7 | B13: PP - 1508 | C13: 200 x 15MM Poly Riser. | D13: 10 | E13: 400 | I13: 2800 | K13: 2000 | M13: 3200 | Q13: 3600 | S13: =SUM(F13:R13) -> 11600 | T13: =S13/E13 -> 29
A14: 8 | B14: PP - 1509 | C14: 225 x 15MM Poly Riser. | D14: 10 | E14: 400 | F14: 8000 | G14: 2800 | H14: 6400 | K14: 6400 | M14: 20000 | Q14: 2000 | S14: =SUM(F14:R14) -> 45600 | T14: =S14/E14 -> 114
A15: 9 | B15: PP - 1512 | C15: Risers 1/2"(15MM)x12"(300MM) | D15: 10 | E15: 300 | I15: 28500 | S15: =SUM(F15:R15) -> 28500 | T15: =S15/E15 -> 95
A16: 9A | B16: PH - 1512 | C16: 300 x 15MM Ply Riser. | D16: 10 | E16: 300 | S16: =SUM(F16:R16) -> 0 | T16: =S16/E16 -> 0
A17: 10 | B17: PPA - 1506 | C17: 150 x 15MM Articulated P.Riser. | D17: 10 | E17: 130 | H17: 1040 | Q17: 1950 | S17: =SUM(F17:R17) -> 2990 | T17: =S17/E17 -> 23
A18: 11 | B18: PPA - 1508 | C18: 200 x 15MM Articulated P.Riser | D18: 10 | E18: 110 | F18: 3300 | H18: 2200 | K18: 3630 | L18: 2200 | M18: 3300 | R18: 550 | S18: =SUM(F18:R18) -> 15180 | T18: =S18/E18 -> 138
A19: 12 | B19: PPA - 1512 | C19: Articulated Riser 1/2"(15mm)x300MM | D19: 10 | E19: 80 | J19: 2320 | Q19: 4480 | R19: 6800 | S19: =SUM(F19:R19) -> 13600 | T19: =S19/E19 -> 170
A20: 13 | B20: FFC - 15 | C20: F/F Couplings 1/2"(15MM) | D20: 100 | E20: 1200 | F20: 6000 | G20: 52800 | H20: 18000 | I20: 40800 | L20: 20400 | M20: 6000 | Q20: 18000 | R20: 24000 | S20: =SUM(F20:R20) -> 186000 | T20: =S20/E20 -> 155
A21: 14 | B21: MFE - 15 | C21: M/F Elbow 1/2" (15MM) | D21: 100 | E21: 1000 | F21: 5000 | G21: 16000 | Q21: 12000 | R21: 12000 | S21: =SUM(F21:R21) -> 45000 | T21: =S21/E21 -> 45
A22: 15 | B22: CAP - 15 | C22: 15MM F.I.Cap. | D22: 50 | E22: 2800 | F22: 14000 | G22: 14000 | K22: 5600 | Q22: 14000 | R22: 8400 | S22: =SUM(F22:R22) -> 56000 | T22: =S22/E22 -> 20
A23: 16 | B23: CUTPL - 15 | C23: 15MM Rigid Cut Off Riser. | D23: 50 | E23: 550 | F23: 16500 | S23: =SUM(F23:R23) -> 16500 | T23: =S23/E23 -> 30
A24: 17 | B24: PP - 2008 | C24: 200 x 20MM Poly Riser. | D24: 10 | E24: 330 | S24: =SUM(F24:R24) -> 0 | T24: =S24/E24 -> 0
A25: 18 | B25: PP - 2010 | C25: Riser 240x20MM Spacer Meter | D25: 10 | E25: 270 | S25: =SUM(F25:R25) -> 0 | T25: =S25/E25 -> 0
A26: 18A | B26: 90447000 | C26: Philmac spacer Meter 20 x 240 | D26: 10 | E26: 270 | F26: 5130 | H26: 3780 | I26: 8100 | N26: 2160 | O26: 2430 | P26: 2700 | Q26: 2700 | R26: 1620 | S26: =SUM(F26:R26) -> 28620 | T26: =S26/E26 -> 106
A27: 19 | B27: PP - 2012 | C27: 300 x 20MM Poly Riser. | D27: 10 | E27: 230 | H27: 6900 | Q27: 1380 | R27: 1610 | S27: =SUM(F27:R27) -> 9890 | T27: =S27/E27 -> 43
A28: 19A | B28: 90442300 | C28: Philmac 300 x 20MM Riser | D28: 10 | E28: 230 | I28: 9200 | S28: =SUM(F28:R28) -> 9200 | T28: =S28/E28 -> 40
A29: 20 | B29: PPA - 2008 | C29: 200 x 20MM Artic Riser. | D29: 5 | E29: 75 | H29: 750 | M29: 525 | S29: =SUM(F29:R29) -> 1275 | T29: =S29/E29 -> 17
A30: 21 | B30: PPA - 2012 | C30: 300 x 20MM Artic Riser | D30: 5 | E30: 50 | H30: 3000 | K30: 2000 | L30: 4000 | M30: 4500 | Q30: 2400 | S30: =SUM(F30:R30) -> 15900 | T30: =S30/E30 -> 318
A31: 22 | B31: MFE - 20 | C31: M/F Elbow 20MM | D31: 50 | E31: 600 | K31: 6000 | S31: =SUM(F31:R31) -> 6000 | T31: =S31/E31 -> 10
A32: 23 | B32: MJC - 18 | C32: 15MM x 1/8" Micro Spray cap | D32: 50 | E32: 2000 | S32: =SUM(F32:R32) -> 0 | T32: =S32/E32 -> 0
A33: 24 | B33: SPASTO | C33: Shrub Adaptor Toro Head | D33: 100 | E33: 2000 | S33: =SUM(F33:R33) -> 0 | T33: =S33/E33 -> 0
A34: 25 | B34: MFA - 15 | C34: 15MM M/F Adaptors. | D34: 50 | E34: 1750 | G34: 7000 | H34: 21000 | Q34: 7000 | R34: 15750 | S34: =SUM(F34:R34) -> 50750 | T34: =S34/E34 -> 29
D35: TOTAL | F35: =SUM(F6:F34) -> 96630 | G35: =SUM(G6:G34) -> 92600 | H35: =SUM(H6:H34) -> 90070 | I35: =SUM(I6:I34) -> 103800 | J35: =SUM(J6:J34) -> 2320 | K35: =SUM(K6:K34) -> 40630 | L35: =SUM(L6:L34) -> 40500 | M35: =SUM(M6:M34) -> 50325 | ... P35: =SUM(P6:P34) -> 2700 | Q35: =SUM(Q7:Q34) -> 98310 | R35: =SUM(R8:R34) -> 80330 | S35: =SUM(F35:R35) -> 702805 | T35: =SUM(T6:T34) -> 1574

Sheet Moulded-2011
A1: 2011 INVOICE No: | F1: 2882 | G1: 2887 | H1: 2895 | I1: 2897 | J1: 2904 | K1: 2907 | L1: 2913 | N1: TOTAL
A2: DATE | F2: 09.02.11 | G2: 09.05.11 | H2: 12.07.11 | I2: 23.08.11 | J2: 28.09.11 | K2: 19.10.11 | L2: 07.12.11 | N2: PCS | O2: BOX
D3: PKGS | F3: 430 | G3: 479 | H3: 483 | I3: 503 | J3: 478 | K3: 483 | L3: 500
A4: Sr. No. | B4: CODE | C4: DESCRIPTION | D4: PACKING
D5: UNIT | E5: BOX
A7: 1 | B7: PP - 1501 | C7: 25 x 15MM Poly Riser | D7: 100 | E7: 2800 | N7: =SUM(F7:M7) -> 0 | O7: =N7/E7 -> 0
A8: 2 | B8: PP - 1502 | C8: 50X15 MM Poly Eriser | D8: 100 | E8: 2800 | N8: =SUM(F8:M8) -> 0 | O8: =N8/E8 -> 0
A9: 3 | B9: PP - 1503 | C9: 80 x 15MM Poly Riser | D9: 50 | E9: 1100 | F9: 3300 | G9: 5500 | I9: 22000 | K9: 9900 | L9: 5500 | N9: =SUM(F9:M9) -> 46200 | O9: =N9/E9 -> 42
A10: 4 | B10: PP - 1504 | C10: 100 x 15MM Poly Riser. | D10: 50 | E10: 1000 | G10: 5000 | H10: 10000 | I10: 15000 | L10: 6000 | N10: =SUM(F10:M10) -> 36000 | O10: =N10/E10 -> 36
A11: 5 | B11: PP - 1505 | C11: 125 X 15 MM Poly Riser | D11: 50 | E11: 800 | I11: 6400 | L11: 8800 | N11: =SUM(F11:M11) -> 15200 | O11: =N11/E11 -> 19
A12: 6 | B12: PP - 1506 | C12: 150 x 15MM Poly Riser. | D12: 50 | E12: 600 | G12: 6000 | H12: 7800 | I12: 7200 | K12: 5400 | L12: 9600 | N12: =SUM(F12:M12) -> 36000 | O12: =N12/E12 -> 60
A13: 6A | B13: PH - 1506 | C13: 150x15 MM Poly Riser | D13: 50 | E13: 600 | K13: 1200 | L13: 1200 | N13: =SUM(F13:M13) -> 2400 | O13: =N13/E13 -> 4
A14: 7 | B14: PP - 1508 | C14: 200 x 15MM Poly Riser. | D14: 10 | E14: 400 | I14: 4000 | K14: 1200 | L14: 2000 | N14: =SUM(F14:M14) -> 7200 | O14: =N14/E14 -> 18
A15: 8 | B15: PP - 1509 | C15: 225 x 15MM Poly Riser. | D15: 10 | E15: 400 | G15: 8000 | H15: 1200 | I15: 12000 | K15: 12000 | N15: =SUM(F15:M15) -> 33200 | O15: =N15/E15 -> 83
A16: 9 | B16: PP - 1512 | C16: Risers 1/2"(15MM)x12"(300MM) | D16: 10 | E16: 300 | H16: 12000 | J16: 29100 | K16: 11700 | N16: =SUM(F16:M16) -> 52800 | O16: =N16/E16 -> 176
A17: 9A | B17: PH - 1512 | C17: 300 x 15MM Ply Riser. | D17: 10 | E17: 300 | K17: 3900 | N17: =SUM(F17:M17) -> 3900 | O17: =N17/E17 -> 13
A18: 10 | B18: PPA - 1506 | C18: 150 x 15MM Articulated P.Riser. | D18: 10 | E18: 130 | F18: 1300 | G18: 650 | H18: 1300 | I18: 1300 | K18: 780 | N18: =SUM(F18:M18) -> 5330 | O18: =N18/E18 -> 41
A19: 11 | B19: PPA - 1508 | C19: 200 x 15MM Articulated P.Riser | D19: 10 | E19: 110 | F19: 3300 | I19: 3740 | J19: 440 | K19: 4070 | N19: =SUM(F19:M19) -> 11550 | O19: =N19/E19 -> 105
A20: 12 | B20: PPA - 1512 | C20: Articulated Riser 1/2"(15mm)x300MM | D20: 10 | E20: 80 | K20: 2400 | N20: =SUM(F20:M20) -> 2400 | O20: =N20/E20 -> 30
A21: 13 | B21: FFC - 15 | C21: F/F Couplings 1/2"(15MM) | D21: 100 | E21: 1200 | G21: 8400 | H21: 6000 | I21: 12000 | J21: 8400 | K21: 3600 | L21: 40800 | N21: =SUM(F21:M21) -> 79200 | O21: =N21/E21 -> 66
A22: 14 | B22: MFE - 15 | C22: M/F Elbow 1/2" (15MM) | D22: 100 | E22: 1000 | G22: 10000 | I22: 5000 | K22: 10000 | L22: 2000 | N22: =SUM(F22:M22) -> 27000 | O22: =N22/E22 -> 27
A23: 15 | B23: CAP - 15 | C23: 15MM F.I.Cap. | D23: 50 | E23: 2800 | G23: 5600 | I23: 14000 | K23: 11200 | L23: 5600 | N23: =SUM(F23:M23) -> 36400 | O23: =N23/E23 -> 13
A24: 16 | B24: CUTPL - 15 | C24: 15MM Rigid Cut Off Riser. | D24: 50 | E24: 550 | H24: 12650 | I24: 3850 | K24: 5500 | L24: 4950 | N24: =SUM(F24:M24) -> 26950 | O24: =N24/E24 -> 49
A25: 16A | B25: CUT-15 | C25: 15 MM Flexi Cut-Off Riser | D25: 50 | E25: 550 | G25: 5500 | I25: 6600 | J25: 3300 | L25: 4950 | N25: =SUM(F25:M25) -> 20350 | O25: =N25/E25 -> 37
A26: 17 | B26: PP - 2008 | C26: 200 x 20MM Poly Riser. | D26: 10 | E26: 330 | N26: =SUM(F26:M26) -> 0 | O26: =N26/E26 -> 0
A27: 18 | B27: PP - 2010 | C27: Riser 240x20MM Spacer Meter | D27: 10 | E27: 270 | N27: =SUM(F27:M27) -> 0 | O27: =N27/E27 -> 0
A28: 18A | B28: 90447000 | C28: Philmac spacer Meter 20 x 240 | D28: 10 | E28: 270 | F28: 10800 | G28: 10800 | H28: 12960 | I28: 3240 | J28: 4050 | N28: =SUM(F28:M28) -> 41850 | O28: =N28/E28 -> 155
A29: 19 | B29: PP - 2012 | C29: 300 x 20MM Poly Riser. | D29: 10 | E29: 230 | G29: 690 | I29: 920 | N29: =SUM(F29:M29) -> 1610 | O29: =N29/E29 -> 7
A30: 19A | B30: 90442300 | C30: Philmac 300 x 20MM Riser | D30: 10 | E30: 230 | N30: =SUM(F30:M30) -> 0 | O30: =N30/E30 -> 0
A31: 20 | B31: PPA - 2008 | C31: 200 x 20MM Artic Riser. | D31: 5 | E31: 75 | F31: 2025 | H31: 1050 | I31: 750 | K31: 1200 | L31: 1200 | N31: =SUM(F31:M31) -> 6225 | O31: =N31/E31 -> 83
A32: 21 | B32: PPA - 2012 | C32: 300 x 20MM Artic Riser | D32: 5 | E32: 50 | G32: 250 | K32: 1000 | N32: =SUM(F32:M32) -> 1250 | O32: =N32/E32 -> 25
A33: 22 | B33: MFE - 20 | C33: M/F Elbow 20MM | D33: 50 | E33: 600 | H33: 6000 | I33: 4800 | J33: 600 | K33: 4800 | L33: 1800 | N33: =SUM(F33:M33) -> 18000 | O33: =N33/E33 -> 30
A34: 23 | B34: MJC - 18 | C34: 15MM x 1/8" Micro Spray cap | D34: 50 | E34: 2000 | N34: =SUM(F34:M34) -> 0 | O34: =N34/E34 -> 0
A35: 24 | B35: SPASTO | C35: Shrub Adaptor Toro Head | D35: 100 | E35: 2000 | N35: =SUM(F35:M35) -> 0 | O35: =N35/E35 -> 0
A36: 25 | B36: MFA - 15 | C36: 15MM M/F Adaptors. | D36: 50 | E36: 1750 | G36: 3500 | I36: 10500 | L36: 10500 | N36: =SUM(F36:M36) -> 24500 | O36: =N36/E36 -> 14
A37: 26 | B37: SPGUARDS | C37: Small Sprinkler Guard | D37: 0 | E37: 360 | L37: 5040 | N37: =SUM(F37:M37) -> 5040 | O37: =N37/E37 -> 14
A38: 27 | B38: SPGUARD | C38: Large Sprinkler Guard | D38: 0 | E38: 150 | L38: 1500 | N38: =SUM(F38:M38) -> 1500 | O38: =N38/E38 -> 10
D39: TOTAL | F39: =SUM(F7:F36) -> 20725 | G39: =SUM(G5:G36) -> 69890 | H39: =SUM(H10:H36) -> 70960 | I39: =SUM(I5:I36) -> 133300 | J39: =SUM(J16:J36) -> 45890 | K39: =SUM(K9:K36) -> 89850 | L39: =SUM(L5:L38) -> 111440 | N39: =SUM(F39:M39) -> 542055 | O39: =SUM(O7:O38) -> 1157

Sheet Moulded-2012
A1: 2012 INVOICE NO | F1: 2916 | G1: 2919 | H1: 2924 | I1: 2927 | J1: 2929 | K1: 2936 | L1: 2938 | M1: 2943 | N1: 2944 | O1: 2949 | P1: 2955 | Q1: 2964 | S1: TOTAL
A2: DATE | F2: 2.1.12 | G2: 17.02.12 | H2: 19.03.12 | I2: 09.04.12 | J2: 26.04.12 | K2: 9.08.12 | L2: 18.06.12 | M2: 30.07.12 | N2: 11.08.12 | O2: 04.09.12 | P2: 16.10.12 | Q2: 10.12.12 | S2: PCS | T2: BOX
D3: PKGS | F3: 445 | G3: 400 | H3: 500 | I3: 9 | J3: 471 | K3: 500 | L3: 8 | M3: 476 | N3: 524 | O3: 451 | P3: 531 | Q3: 422
A4: Sr. No. | B4: CODE | C4: DESCRIPTION | D4: PACKING
D5: UNIT | E5: BOX
A7: 1 | B7: PP - 1501 | C7: 25 x 15MM Poly Riser | D7: 100 | E7: 2800 | F7: 50400 | G7: 28000 | H7: 22400 | J7: 11200 | K7: 28000 | M7: 8400 | N7: 14000 | O7: 5600 | S7: =SUM(F7:Q7) -> 168000 | T7: =S7/E7 -> 60
A8: 3 | B8: PP - 1503 | C8: 80 x 15MM Poly Riser | D8: 50 | E8: 1100 | G8: 15400 | H8: 3300 | M8: 6600 | N8: 5500 | O8: 7700 | Q8: 8800 | S8: =SUM(F8:Q8) -> 47300 | T8: =S8/E8 -> 43
A9: 4 | B9: PP - 1504 | C9: 100 x 15MM Poly Riser. | D9: 50 | E9: 1000 | G9: 6000 | H9: 9000 | K9: 6000 | M9: 5000 | O9: 10000 | Q9: 10000 | S9: =SUM(F9:Q9) -> 46000 | T9: =S9/E9 -> 46
A10: 5 | B10: PP - 1505 | C10: 125 X 15 MM Poly Riser | D10: 50 | E10: 800 | G10: 6400 | H10: 4800 | M10: 3200 | O10: 7200 | Q10: 8000 | S10: =SUM(F10:Q10) -> 29600 | T10: =S10/E10 -> 37
A11: 6 | B11: PP - 1506 | C11: 150 x 15MM Poly Riser. | D11: 50 | E11: 600 | G11: 7200 | H11: 7800 | K11: 4800 | M11: 3600 | N11: 21600 | S11: =SUM(F11:Q11) -> 45000 | T11: =S11/E11 -> 75
A12: 6A | B12: PH - 1506 | C12: 150x15 MM Poly Riser | D12: 50 | E12: 600 | M12: 3000 | N12: 6000 | O12: 1200 | S12: =SUM(F12:Q12) -> 10200 | T12: =S12/E12 -> 17
A13: 7 | B13: PP - 1508 | C13: 200 x 15MM Poly Riser. | D13: 10 | E13: 400 | J13: 2000 | M13: 2000 | O13: 4000 | S13: =SUM(F13:Q13) -> 8000 | T13: =S13/E13 -> 20
A14: 8 | B14: PP - 1509 | C14: 225 x 15MM Poly Riser. | D14: 10 | E14: 400 | G14: 6800 | H14: 8000 | J14: 4400 | K14: 4800 | M14: 4000 | O14: 8000 | Q14: 8000 | S14: =SUM(F14:Q14) -> 44000 | T14: =S14/E14 -> 110
A15: 9 | B15: PP - 1512 | C15: Risers 1/2"(15MM)x12"(300MM) | D15: 10 | E15: 300 | G15: 6000 | H15: 6000 | J15: 3600 | K15: 3900 | M15: 6000 | N15: 3000 | O15: 21000 | Q15: 20100 | S15: =SUM(F15:Q15) -> 69600 | T15: =S15/E15 -> 232
A16: 9A | B16: 90441300 | C16: 90441300 P/Riser MXM 15x15x300 | D16: 10 | E16: 300 | J16: 900 | N16: 1800 | O16: 3300 | P16: 2100 | S16: =SUM(F16:Q16) -> 8100 | T16: =S16/E16 -> 27
A17: 9B | B17: PET 1512 | C17: Full Threadd Roser 15mmx300 MM | D17: 10 | E17: 300 | K17: 2100 | N17: 8100 | S17: =SUM(F17:Q17) -> 10200 | T17: =S17/E17 -> 34
A18: 10 | B18: PPA - 1506 | C18: 150 x 15MM Articulated P.Riser. | D18: 10 | E18: 130 | H18: 910 | J18: 780 | K18: 2340 | M18: 650 | N18: 1300 | S18: =SUM(F18:Q18) -> 5980 | T18: =S18/E18 -> 46
A19: 11 | B19: PPA - 1508 | C19: 200 x 15MM Articulated P.Riser | D19: 10 | E19: 110 | K19: 2640 | M19: 330 | N19: 880 | S19: =SUM(F19:Q19) -> 3850 | T19: =S19/E19 -> 35
A20: 12 | B20: PPA - 1512 | C20: Articulated Riser 1/2"(15mm)x300MM | D20: 10 | E20: 80 | J20: 1520 | K20: 2640 | M20: 1200 | O20: 1840 | P20: 2000 | S20: =SUM(F20:Q20) -> 9200 | T20: =S20/E20 -> 115
A21: 13 | B21: FFC - 15 | C21: F/F Couplings 1/2"(15MM) | D21: 100 | E21: 1200 | F21: 9600 | G21: 15600 | H21: 18000 | K21: 12000 | M21: 18000 | O21: 18000 | S21: =SUM(F21:Q21) -> 91200 | T21: =S21/E21 -> 76
A22: 14 | B22: MFE - 15 | C22: M/F Elbow 1/2" (15MM) | D22: 100 | E22: 1000 | F22: 8000 | M22: 10000 | N22: 10000 | S22: =SUM(F22:Q22) -> 28000 | T22: =S22/E22 -> 28
A23: 15 | B23: CAP - 15 | C23: 15MM F.I.Cap. | D23: 50 | E23: 2800 | G23: 5600 | H23: 8400 | M23: 11200 | O23: 8400 | S23: =SUM(F23:Q23) -> 33600 | T23: =S23/E23 -> 12
A24: 16 | B24: CUTPL - 15 | C24: 15MM Rigid Cut Off Riser. | D24: 50 | E24: 550 | F24: 550 | H24: 5500 | J24: 3850 | K24: 550 | M24: 3300 | O24: 6600 | S24: =SUM(F24:Q24) -> 20350 | T24: =S24/E24 -> 37
A25: 16A | B25: CUT-15 | C25: 15 MM Flexi Cut-Off Riser | D25: 50 | E25: 550 | F25: 550 | H25: 7150 | J25: 3850 | M25: 3850 | O25: 11000 | S25: =SUM(F25:Q25) -> 26400 | T25: =S25/E25 -> 48
A26: 16B | B26: CUTMF 15 | C26: 15 mm M/F Cut off Riser | D26: 10 | E26: 1200 | K26: 6000 | M26: 9600 | O26: 10800 | S26: =SUM(F26:Q26) -> 26400 | T26: =S26/E26 -> 22
A27: 17 | B27: PP - 2008 | C27: 200 x 20MM Poly Riser. | D27: 10 | E27: 330 | K27: 660 | S27: =SUM(F27:Q27) -> 660 | T27: =S27/E27 -> 2
A28: 18A | B28: 90447000 | C28: Philmac spacer Meter 20 x 240 | D28: 10 | E28: 270 | G28: 5400 | H28: 9990 | K28: 7560 | M28: 1620 | N28: 3780 | P28: 3240 | S28: =SUM(F28:Q28) -> 31590 | T28: =S28/E28 -> 117
A29: 19 | B29: PP - 2012 | C29: 300 x 20MM Poly Riser. | D29: 10 | E29: 230 | G29: 1840 | H29: 230 | M29: 2530 | N29: 2530 | S29: =SUM(F29:Q29) -> 7130 | T29: =S29/E29 -> 31
A30: 19A | B30: 90442300 | C30: 90442300 P/Riser MXM 20x20x300 mm | D30: 10 | E30: 230 | K30: 3450 | M30: 690 | N30: 2300 | S30: =SUM(F30:Q30) -> 6440 | T30: =S30/E30 -> 28
A31: 20 | B31: PPA - 2008 | C31: 200 x 20MM Artic Riser. | D31: 5 | E31: 75 | K31: 525 | M31: 225 | O31: 600 | S31: =SUM(F31:Q31) -> 1350 | T31: =S31/E31 -> 18
A32: 21 | B32: PPA - 2012 | C32: 300 x 20MM Artic Riser | D32: 5 | E32: 50 | G32: 400 | J32: 950 | K32: 1150 | M32: 2000 | N32: 2000 | P32: 2000 | S32: =SUM(F32:Q32) -> 8500 | T32: =S32/E32 -> 170
A33: 23 | B33: PP 2512 | C33: 300 x 25MM Poly Riser. | D33: 10 | E33: 160 | F33: 3200 | G33: 1600 | H33: 2720 | M33: 960 | N33: 2080 | P33: 1120 | S33: =SUM(F33:Q33) -> 11680 | T33: =S33/E33 -> 73
A34: 23A | B34: 90443300 | C34: 90443300 P/Riser MXM 25x25x300 mm | D34: 10 | E34: 160 | K34: 3040 | N34: 3040 | P34: 3040 | S34: =SUM(F34:Q34) -> 9120 | T34: =S34/E34 -> 57
A35: 24 | B35: PPA 2512 | C35: Articulated Riser 1"(25 mm)x300MM | D35: 5 | E35: 35 | F35: 770 | G35: 245 | H35: 70 | K35: 315 | M35: 315 | N35: 595 | Q35: 1015 | S35: =SUM(F35:Q35) -> 3325 | T35: =S35/E35 -> 95
A36: 25 | B36: MFE 25 | C36: M/F Elbow 25MM (1") | D36: 50 | E36: 350 | F36: 7700 | G36: 2450 | H36: 5600 | J36: 2100 | M36: 700 | N36: 3150 | O36: 1050 | S36: =SUM(F36:Q36) -> 22750 | T36: =S36/E36 -> 65
A37: 26 | B37: MFA - 15 | C37: 15MM M/F Adaptors. | D37: 50 | E37: 1750 | J37: 10500 | K37: 7000 | M37: 5250 | N37: 10500 | S37: =SUM(F37:Q37) -> 33250 | T37: =S37/E37 -> 19
D38: TOTAL | F38: =SUM(F7:F37) -> 80770 | G38: =SUM(G7:G37) -> 108935 | H38: =SUM(H7:H37) -> 119870 | I38: =SUM(I7:I37) -> 0 | J38: =SUM(J7:J37) -> 45650 | K38: =SUM(K7:K37) -> 99470 | L38: =SUM(L7:L37) -> 0 | M38: =SUM(M7:M37) -> 114220 | ... Q38: =SUM(Q7:Q37) -> 55915 | S38: =SUM(S7:S37) -> 866775 | T38: =SUM(T7:T37) -> 1795

Sheet Moulded-2013
A1: MOULDED - 2013 INVOICE NO | F1: 2969 | G1: 2974 | H1: 2978 | I1: 2983 | J1: 2991 | K1: 2999 | L1: 3004 | M1: 3011 | N1: 3024 | O1: 3028 | P1: TOTAL
A2: DATE | F2: 07.01.13 | G2: 08.02.13 | H2: 25.02.13 | I2: 18.03.13 | J2: 29.04.13 | K2: 18.06.13 | L2: 23.07.13 | M2: 19.08.13 | N2: 24.10.13 | O2: 19.11.13 | P2: PCS | Q2: BOX
D3: PKGS | F3: 133 | G3: 140 | H3: 62 | I3: 88 | J3: 199 | K3: 201 | L3: 142 | M3: 264 | N3: 93 | O3: 118
A4: Sr. No. | B4: CODE | C4: DESCRIPTION | D4: PACKING | F4: PCS | G4: PCS | H4: PCS | I4: PCS | J4: PCS | K4: PCS | L4: PCS | M4: PCS | N4: PCS | O4: PCS
D5: UNIT | E5: BOX
A7: 1 | B7: PP - 1501 | C7: 25 x 15MM Poly Riser | D7: 100 | E7: 2800 | F7: 30800 | G7: 14000 | J7: 33600 | K7: 39200 | L7: 28000 | M7: 28000 | P7: =SUM(F7:O7) -> 173600 | Q7: =P7/E7 -> 62
A8: 2 | B8: PP - 1502 | C8: 50X15 MM Poly Eriser | D8: 100 | E8: 2000 | L8: 10000 | M8: 20000 | P8: =SUM(F8:O8) -> 30000 | Q8: =P8/E8 -> 15
A9: 3 | B9: PP - 1503 | C9: 80 x 15MM Poly Riser | D9: 50 | E9: 1100 | F9: 5500 | H9: 4400 | I9: 6600 | K9: 22000 | L9: 9900 | M9: 1100 | P9: =SUM(F9:O9) -> 49500 | Q9: =P9/E9 -> 45
A10: 4 | B10: PP - 1504 | C10: 100 x 15MM Poly Riser. | D10: 50 | E10: 1000 | F10: 5000 | G10: 10000 | J10: 10000 | K10: 10000 | L10: 10000 | P10: =SUM(F10:O10) -> 45000 | Q10: =P10/E10 -> 45
A11: 5 | B11: PP - 1505 | C11: 125 X 15 MM Poly Riser | D11: 50 | E11: 800 | F11: 4800 | I11: 8000 | J11: 8000 | K11: 8000 | L11: 8000 | P11: =SUM(F11:O11) -> 36800 | Q11: =P11/E11 -> 46
A12: 6 | B12: PP - 1506 | C12: 150 x 15MM Poly Riser. | D12: 50 | E12: 600 | G12: 3000 | H12: 2400 | J12: 6000 | K12: 6000 | L12: 6000 | M12: 6000 | O12: 6000 | P12: =SUM(F12:O12) -> 35400 | Q12: =P12/E12 -> 59
A13: 7 | B13: PP - 1508 | C13: 200 x 15MM Poly Riser. | D13: 10 | E13: 400 | K13: 1200 | L13: 1200 | M13: 2000 | P13: =SUM(F13:O13) -> 4400 | Q13: =P13/E13 -> 11
A14: 8 | B14: PP - 1509 | C14: 225 x 15MM Poly Riser. | D14: 10 | E14: 400 | F14: 4000 | G14: 6800 | H14: 3200 | J14: 8000 | K14: 8000 | L14: 4000 | M14: 12000 | P14: =SUM(F14:O14) -> 46000 | Q14: =P14/E14 -> 115
A15: 9 | B15: PP - 1512 | C15: Risers 1/2"(15MM)x12"(300MM) | D15: 10 | E15: 300 | F15: 6000 | N15: 900 | O15: 900 | P15: =SUM(F15:O15) -> 7800 | Q15: =P15/E15 -> 26
A16: 10 | B16: PPA - 1506 | C16: 150 x 15MM Articulated P.Riser. | D16: 10 | E16: 130 | J16: 1300 | K16: 1300 | M16: 2600 | N16: 1300 | O16: 1300 | P16: =SUM(F16:O16) -> 7800 | Q16: =P16/E16 -> 60
A17: 11 | B17: PPA - 1508 | C17: 200 x 15MM Articulated P.Riser | D17: 10 | E17: 110 | F17: 1100 | G17: 770 | I17: 2310 | J17: 1100 | K17: 1100 | L17: 1100 | M17: 1100 | N17: 1100 | O17: 1100 | P17: =SUM(F17:O17) -> 10780 | Q17: =P17/E17 -> 98
A18: 12 | B18: PPA - 1512 | C18: Articulated Riser 1/2"(15mm)x300MM | D18: 10 | E18: 80 | G18: 1600 | N18: 800 | O18: 800 | P18: =SUM(F18:O18) -> 3200 | Q18: =P18/E18 -> 40
A19: 13 | B19: FFC - 15 | C19: F/F Couplings 1/2"(15MM) | D19: 100 | E19: 1200 | F19: 24000 | G19: 18000 | I19: 12000 | J19: 36000 | K19: 12000 | L19: 12000 | M19: 12000 | P19: =SUM(F19:O19) -> 126000 | Q19: =P19/E19 -> 105
A20: 14 | B20: MFE - 15 | C20: M/F Elbow 1/2" (15MM) | D20: 100 | E20: 1000 | N20: 10000 | P20: =SUM(F20:O20) -> 10000 | Q20: =P20/E20 -> 10
A21: 15 | B21: CAP - 15 | C21: 15MM F.I.Cap. | D21: 50 | E21: 2800 | F21: 5600 | J21: 8400 | K21: 19600 | L21: 5600 | M21: 5600 | P21: =SUM(F21:O21) -> 44800 | Q21: =P21/E21 -> 16
A22: 16 | B22: CUTPL - 15 | C22: 15MM Rigid Cut Off Riser. | D22: 50 | E22: 550 | F22: 5500 | H22: 5500 | I22: 5500 | J22: 5500 | K22: 5500 | M22: 5500 | P22: =SUM(F22:O22) -> 33000 | Q22: =P22/E22 -> 60
A23: 16A | B23: CUT-15 | C23: 15 MM Flexi Cut-Off Riser | D23: 50 | E23: 550 | F23: 5500 | H23: 5500 | I23: 5500 | J23: 5500 | K23: 5500 | M23: 5500 | P23: =SUM(F23:O23) -> 33000 | Q23: =P23/E23 -> 60
A24: 16B | B24: CUTMF 15 | C24: 15 mm M/F Cut off Riser | D24: 10 | E24: 1200 | F24: 4800 | H24: 4800 | J24: 9600 | K24: 4800 | M24: 4800 | P24: =SUM(F24:O24) -> 28800 | Q24: =P24/E24 -> 24
A25: 17 | B25: PP 2002 | C25: 50 x 20MM Poly Riser | D25: 50 | E25: 1300 | M25: 5200 | O25: 2600 | P25: =SUM(F25:O25) -> 7800
A26: 18 | B26: PP 2003 | C26: 80 X 20MM Poly Riser | D26: 50 | E26: 800 | M26: 4000 | O26: 2400 | P26: =SUM(F26:O26) -> 6400
A27: 20A | B27: 90447000 | C27: Philmac spacer Meter 20 x 240 | D27: 10 | E27: 270 | H27: 1080 | I27: 5670 | J27: 5400 | K27: 5400 | L27: 5400 | M27: 10800 | O27: 2700 | P27: =SUM(F27:O27) -> 36450 | Q27: =P27/E27 -> 135
A28: 21 | B28: PP - 2012 | C28: 300 x 20MM Poly Riser. | D28: 10 | E28: 230 | F28: 1150 | G28: 2070 | J28: 2300 | K28: 2300 | L28: 2300 | O28: 2300 | P28: =SUM(F28:O28) -> 12420 | Q28: =P28/E28 -> 54
A29: 21A | B29: 90442300 | C29: 90442300 P/Riser MXM 20x20x300 mm | D29: 10 | E29: 230 | F29: 1150 | G29: 1150 | H29: 1150 | J29: 2300 | M29: 2300 | N29: 2300 | O29: 2300 | P29: =SUM(F29:O29) -> 12650 | Q29: =P29/E29 -> 55
A30: 22 | B30: PPA - 2008 | C30: 200 x 20MM Artic Riser. | D30: 5 | E30: 75 | F30: 525 | G30: 525 | H30: 975 | J30: 750 | K30: 750 | L30: 750 | M30: 2250 | N30: 750 | O30: 750 | P30: =SUM(F30:O30) -> 8025 | Q30: =P30/E30 -> 107
A31: 23 | B31: PPA - 2012 | C31: 300 x 20MM Artic Riser | D31: 5 | E31: 50 | G31: 1000 | M31: 1000 | P31: =SUM(F31:O31) -> 2000 | Q31: =P31/E31 -> 40
A32: 25 | B32: FFC-20 | C32: 20MM F/F Couplings | D32: 50 | E32: 800 | M32: 4800 | P32: =SUM(F32:O32) -> 4800
A33: 26 | B33: PP 2512 | C33: 300 x 25MM Poly Riser. | D33: 10 | E33: 160 | K33: 1600 | L33: 1600 | O33: 1600 | P33: =SUM(F33:O33) -> 4800 | Q33: =P33/E33 -> 30
A34: 26A | B34: 90443300 | C34: 90443300 P/Riser MXM 25x25x300 mm | D34: 10 | E34: 160 | M34: 2080 | N34: 1600 | O34: 1600 | P34: =SUM(F34:O34) -> 5280 | Q34: =P34/E34 -> 33
A35: 27 | B35: PPA 2512 | C35: Articulated Riser 1"(25 mm)x300MM | D35: 5 | E35: 35 | G35: 700 | N35: 700 | O35: 350 | P35: =SUM(F35:O35) -> 1750 | Q35: =P35/E35 -> 50
A36: 31 | B36: MFA - 15 | C36: 15MM M/F Adaptors. | D36: 50 | E36: 1750 | F36: 5250 | J36: 10500 | K36: 5250 | L36: 5250 | M36: 7000 | P36: =SUM(F36:O36) -> 33250 | Q36: =P36/E36 -> 19
A38: TOTAL | F38: =SUM(F7:F37) -> 110675 | G38: =SUM(G7:G37) -> 59615 | H38: =SUM(H7:H37) -> 29005 | I38: =SUM(I7:I37) -> 45580 | J38: =SUM(J7:J37) -> 154250 | K38: =SUM(K7:K37) -> 159500 | L38: =SUM(L7:L37) -> 111100 | M38: =SUM(M7:M37) -> 145630 | ... P38: =SUM(P7:P37) -> 861505
A39: TOTAL BOXES | Q39: =SUM(Q7:Q37) -> 1420

Sheet Moulded-2014
A1: MOULDED - 2014 INVOICE NO | F1: 3039 | G1: 3046 | H1: 3054 | I1: 3059 | J1: 3063 | K1: 3068 | L1: 3075 | M1: 3077 | N1: 3080 | O1: 3086 | P1: TOTAL
A2: DATE | F2: 03.01.14 | G2: 25.02.14 | H2: 08.04.14 | I2: 08.05.14 | J2: 12.06.14 | K2: 21.07.14 | L2: 25.09.14 | M2: 13.10.14 | N2: 13.11.14 | O2: 24.12.14 | P2: PCS | Q2: BOX
D3: PKGS | F3: 425 | G3: 486 | H3: 497 | I3: 198 | J3: 484 | K3: 45 | L3: 138 | M3: 18 | N3: 125 | O3: 227
A4: Sr. No. | B4: CODE | C4: DESCRIPTION | D4: PACKING | F4: PCS | G4: PCS | H4: PCS | I4: PCS | J4: PCS | K4: PCS | L4: PCS | M4: PCS | N4: PCS | O4: PCS
D5: UNIT | E5: BOX
A7: 1 | B7: PP - 1501 | C7: 25 x 15MM Poly Riser | D7: 100 | E7: 2800 | F7: 28000 | G7: 28000 | H7: 56000 | J7: 28000 | P7: =SUM(F7:O7) -> 140000 | Q7: =P7/E7 -> 50
A8: 1A | B8: PP - 1501 | C8: 25 x 15MM Poly Riser | D8: 100 | E8: 2000 | M8: 16000 | N8: 28000 | O8: 28000 | P8: =SUM(F8:O8) -> 72000 | Q8: =P8/E8 -> 36
A9: 2 | B9: PP - 1502 | C9: 50X15 MM Poly Eriser | D9: 100 | E9: 2000 | F9: 20000 | G9: 20000 | H9: 40000 | J9: 20000 | M9: 20000 | N9: 20000 | O9: 10000 | P9: =SUM(F9:O9) -> 150000 | Q9: =P9/E9 -> 75
A10: 3 | B10: PP - 1503 | C10: 80 x 15MM Poly Riser | D10: 50 | E10: 1100 | F10: 19800 | G10: 11000 | H10: 22000 | J10: 11000 | L10: 11000 | N10: 11000 | O10: 11000 | P10: =SUM(F10:O10) -> 96800 | Q10: =P10/E10 -> 88
A11: 4 | B11: PP - 1504 | C11: 100 x 15MM Poly Riser. | D11: 50 | E11: 1000 | F11: 18000 | G11: 20000 | H11: 10000 | I11: 10000 | L11: 10000 | N11: 10000 | O11: 10000 | P11: =SUM(F11:O11) -> 88000 | Q11: =P11/E11 -> 88
A12: 5 | B12: PP - 1505 | C12: 125 X 15 MM Poly Riser | D12: 50 | E12: 800 | F12: 8000 | G12: 16000 | H12: 8000 | I12: 8800 | L12: 4000 | P12: =SUM(F12:O12) -> 44800 | Q12: =P12/E12 -> 56
A13: 6 | B13: PP - 1506 | C13: 150 x 15MM Poly Riser. | D13: 50 | E13: 600 | F13: 6000 | G13: 19200 | H13: 12000 | J13: 6000 | L13: 6000 | O13: 6000 | P13: =SUM(F13:O13) -> 55200 | Q13: =P13/E13 -> 92
A14: 6A | B14: 90441200 | C14: 90441200 150x15 MM Poly Riser | D14: 50 | E14: 600 | H14: 3000 | J14: 1200 | P14: =SUM(F14:O14) -> 4200 | Q14: =P14/E14 -> 7
A15: 7 | B15: PP - 1508 | C15: 200 x 15MM Poly Riser. | D15: 10 | E15: 400 | G15: 1200 | H15: 2400 | J15: 4400 | K15: 2000 | P15: =SUM(F15:O15) -> 10000 | Q15: =P15/E15 -> 25
A16: 8 | B16: PP - 1509 | C16: 225 x 15MM Poly Riser. | D16: 10 | E16: 400 | F16: 8000 | G16: 8000 | H16: 12000 | J16: 20000 | L16: 4000 | N16: 4000 | O16: 4000 | P16: =SUM(F16:O16) -> 60000 | Q16: =P16/E16 -> 150
A17: 9 | B17: PP - 1512 | C17: Risers 1/2"(15MM)x12"(300MM) | D17: 10 | E17: 300 | F17: 34200 | G17: 21000 | H17: 9000 | I17: 18000 | L17: 3000 | O17: 9000 | P17: =SUM(F17:O17) -> 94200 | Q17: =P17/E17 -> 314
A18: 9A | B18: 90441300 | C18: 90441300 P/Riser MXM 15x15x300 | D18: 10 | E18: 300 | G18: 1200 | H18: 3000 | J18: 3000 | P18: =SUM(F18:O18) -> 7200 | Q18: =P18/E18 -> 24
A19: 9B | B19: PET 1512 | C19: Full Threadd Roser 15mmx300 MM | D19: 10 | E19: 300 | F19: 8100 | G19: 8100 | H19: 12600 | J19: 8100 | O19: 3000 | P19: =SUM(F19:O19) -> 39900 | Q19: =P19/E19 -> 133
A20: 10 | B20: PPA - 1506 | C20: 150 x 15MM Articulated P.Riser. | D20: 10 | E20: 130 | F20: 1300 | I20: 1300 | J20: 1300 | N20: 1300 | P20: =SUM(F20:O20) -> 5200 | Q20: =P20/E20 -> 40
A21: 11 | B21: PPA - 1508 | C21: 200 x 15MM Articulated P.Riser | D21: 10 | E21: 110 | F21: 1100 | G21: 1100 | H21: 1100 | I21: 2200 | J21: 1100 | P21: =SUM(F21:O21) -> 6600 | Q21: =P21/E21 -> 60
A22: 12 | B22: PPA - 1512 | C22: Articulated Riser 1/2"(15mm)x300MM | D22: 10 | E22: 80 | F22: 2400 | G22: 1600 | H22: 4000 | I22: 1600 | J22: 1600 | L22: 800 | O22: 800 | P22: =SUM(F22:O22) -> 12800 | Q22: =P22/E22 -> 160
A23: 13 | B23: FFC - 15 | C23: F/F Couplings 1/2"(15MM) | D23: 100 | E23: 1200 | F23: 24000 | G23: 24000 | H23: 24000 | J23: 24000 | K23: 24000 | L23: 24000 | N23: 24000 | O23: 24000 | P23: =SUM(F23:O23) -> 192000 | Q23: =P23/E23 -> 160
A24: 14 | B24: MFE - 15 | C24: M/F Elbow 1/2" (15MM) | D24: 100 | E24: 1000 | F24: 10000 | G24: 14000 | H24: 11000 | J24: 10000 | K24: 10000 | O24: 1000 | P24: =SUM(F24:O24) -> 56000 | Q24: =P24/E24 -> 56
A25: 15 | B25: CAP - 15 | C25: 15MM F.I.Cap. | D25: 50 | E25: 2800 | F25: 11200 | G25: 22400 | H25: 16800 | J25: 8400 | L25: 11200 | O25: 8400 | P25: =SUM(F25:O25) -> 78400 | Q25: =P25/E25 -> 28
A26: 16 | B26: CUTPL - 15 | C26: 15MM Rigid Cut Off Riser. | D26: 50 | E26: 550 | F26: 550 | G26: 6600 | H26: 11000 | I26: 5500 | J26: 5500 | N26: 5500 | O26: 5500 | P26: =SUM(F26:O26) -> 40150 | Q26: =P26/E26 -> 73
A27: 16A | B27: CUT-15 | C27: 15 MM Flexi Cut-Off Riser | D27: 50 | E27: 550 | F27: 550 | G27: 6600 | H27: 5500 | I27: 11000 | K27: 5500 | L27: 5500 | N27: 5500 | O27: 5500 | P27: =SUM(F27:O27) -> 45650 | Q27: =P27/E27 -> 83
A28: 16B | B28: CUTMF 15 | C28: 15 mm M/F Cut off Riser | D28: 10 | E28: 1200 | F28: 12000 | H28: 31200 | J28: 19200 | P28: =SUM(F28:O28) -> 62400 | Q28: =P28/E28 -> 52
A29: 17 | B29: PP 2002 | C29: 50 x 20MM Poly Riser | D29: 50 | E29: 1300 | F29: 2600 | G29: 5200 | H29: 5200 | J29: 13000 | P29: =SUM(F29:O29) -> 26000 | Q29: =P29/E29 -> 20
A30: 18 | B30: PP 2003 | C30: 80 X 20MM Poly Riser | D30: 50 | E30: 800 | F30: 2400 | G30: 4000 | H30: 4000 | J30: 11200 | P30: =SUM(F30:O30) -> 21600 | Q30: =P30/E30 -> 27
B31: PP 2006 | C31: 150 X 20MM Poly Riser | D31: 10 | E31: 500 | G31: 5000 | H31: 500 | P31: =SUM(F31:O31) -> 5500 | Q31: =P31/E31 -> 11
B32: PP 2006 | C32: 150 X 20MM Poly Riser | D32: 10 | E32: 450 | J32: 9450 | O32: 2250 | P32: =SUM(F32:O32) -> 11700 | Q32: =P32/E32 -> 26
A33: 20A | B33: 90447000 | C33: Philmac spacer Meter 20 x 240 | D33: 10 | E33: 270 | F33: 2700 | G33: 10800 | H33: 5670 | J33: 21600 | P33: =SUM(F33:O33) -> 40770 | Q33: =P33/E33 -> 151
A34: 21 | B34: PP - 2012 | C34: 300 x 20MM Poly Riser. | D34: 10 | E34: 230 | F34: 2300 | G34: 4600 | H34: 2300 | J34: 6900 | P34: =SUM(F34:O34) -> 16100 | Q34: =P34/E34 -> 70
A35: 21A | B35: 90442300 | C35: 90442300 P/Riser MXM 20x20x300 mm | D35: 10 | E35: 230 | F35: 2300 | H35: 2300 | J35: 2300 | P35: =SUM(F35:O35) -> 6900 | Q35: =P35/E35 -> 30
A36: 22 | B36: PPA - 2008 | C36: 200 x 20MM Artic Riser. | D36: 5 | E36: 75 | N36: 750 | P36: =SUM(F36:O36) -> 750 | Q36: =P36/E36 -> 10
A37: 23 | B37: PPA - 2012 | C37: 300 x 20MM Artic Riser | D37: 5 | E37: 50 | F37: 500 | G37: 500 | H37: 1000 | J37: 2000 | L37: 1000 | O37: 500 | P37: =SUM(F37:O37) -> 5500 | Q37: =P37/E37 -> 110
A38: 24 | B38: MFE - 20 | C38: M/F Elbow 20MM | D38: 50 | E38: 600 | F38: 1800 | H38: 6000 | J38: 1200 | P38: =SUM(F38:O38) -> 9000 | Q38: =P38/E38 -> 15
A39: 25 | B39: FFC-20 | C39: 20MM F/F Couplings | D39: 50 | E39: 800 | F39: 3200 | G39: 3200 | H39: 7200 | J39: 6400 | L39: 4000 | P39: =SUM(F39:O39) -> 24000 | Q39: =P39/E39 -> 30
B40: PP 2504 | C40: 100 X 25MM Poly Riser | D40: 10 | E40: 400 | G40: 800 | H40: 800 | N40: 400 | P40: =SUM(F40:O40) -> 2000 | Q40: =P40/E40 -> 5
B41: PP 2506 | C41: 150 X 25MM Poly Riser | D41: 10 | E41: 300 | G41: 3900 | H41: 1200 | I41: 2100 | L41: 4200 | O41: 2100 | P41: =SUM(F41:O41) -> 13500 | Q41: =P41/E41 -> 45
...

Sheet Moulded-2015
A1: MOULDED - 2015 INVOICE NO | F1: 3088 | G1: 3092 | H1: 3095 | I1: 3096 | J1: 3097 | K1: 3108 | L1: 3113 | M1: 3121 | N1: 3123 | O1: 3124 | Q1: TOTAL | T1: 3124
A2: DATE | F2: 08.01.15 | G2: 29.01.15 | H2: 04.03.15 | I2: 20.03.15 | J2: 01.04.15 | K2: 15.07.15 | L2: 23.09.15 | M2: 20.11.15 | N2: 04.12.15 | O2: 21.12.15 | Q2: PCS | R2: BOX
D3: PKGS | F3: 13 | G3: 160 | H3: 162 | I3: 98 | J3: 200 | K3: 56 | L3: 149 | M3: 108 | N3: 130 | O3: 84
A4: Sr. No. | B4: CODE | C4: DESCRIPTION | D4: PACKING | F4: PCS | G4: PCS | H4: PCS | I4: PCS | J4: PCS | K4: PCS | L4: PCS | M4: PCS | N4: PCS | O4: PCS | P4: PCS
D5: UNIT | E5: BOX
A7: 1A | B7: PP - 1501 | C7: 25 x 15MM Poly Riser | D7: 100 | E7: 2000 | G7: 28000 | N7: 16000 | O7: 4000 | Q7: =SUM(F7:P7) -> 48000 | R7: =Q7/E7 -> 24 | T7: =HLOOKUP($T$1,$F$1:$P$48,8,FALSE) -> 0 | U7: =$T7/$E7 -> 0
A8: 1B | B8: PP - 1501 | C8: 25 x 15MM Poly Riser | D8: 100 | E8: 1600 | I8: 27200 | Q8: =SUM(F8:P8) -> 27200 | R8: =Q8/E8 -> 17 | T8: =HLOOKUP($T$1,$F$1:$P$48,9,FALSE) -> 6000 | U8: =$T8/$E8 -> 3.75
A9: 2 | B9: PP - 1502 | C9: 50X15 MM Poly Eriser | D9: 100 | E9: 2000 | H9: 10000 | N9: 14000 | O9: 6000 | Q9: =SUM(F9:P9) -> 30000 | R9: =Q9/E9 -> 15 | T9: =HLOOKUP($T$1,$F$1:$P$48,10,FALSE) -> 0 | U9: =$T9/$E9 -> 0
A10: 3 | B10: PP - 1503 | C10: 80 x 15MM Poly Riser | D10: 50 | E10: 1100 | H10: 11000 | L10: 11000 | N10: 11000 | Q10: =SUM(F10:P10) -> 33000 | R10: =Q10/E10 -> 30 | T10: =HLOOKUP($T$1,$F$1:$P$48,11,FALSE) -> 0 | U10: =$T10/$E10 -> 0
A11: 4 | B11: PP - 1504 | C11: 100 x 15MM Poly Riser. | D11: 50 | E11: 1000 | H11: 10000 | L11: 10000 | M11: 10000 | N11: 10000 | Q11: =SUM(F11:P11) -> 40000 | R11: =Q11/E11 -> 40 | T11: =HLOOKUP($T$1,$F$1:$P$48,12,FALSE) -> 4800 | U11: =$T11/$E11 -> 4.8
A12: 5 | B12: PP - 1505 | C12: 125 X 15 MM Poly Riser | D12: 50 | E12: 800 | I12: 8000 | L12: 4800 | O12: 4800 | Q12: =SUM(F12:P12) -> 17600 | R12: =Q12/E12 -> 22 | T12: =HLOOKUP($T$1,$F$1:$P$48,13,FALSE) -> 0 | U12: =$T12/$E12 -> 0
A13: 6 | B13: PP - 1506 | C13: 150 x 15MM Poly Riser. | D13: 50 | E13: 600 | G13: 6000 | I13: 12000 | L13: 6000 | N13: 6000 | Q13: =SUM(F13:P13) -> 30000 | R13: =Q13/E13 -> 50 | T13: =HLOOKUP($T$1,$F$1:$P$48,14,FALSE) -> 0 | U13: =$T13/$E13 -> 0
A14: 6A | B14: 90441200 | C14: 90441200 150x15 MM Poly Riser | D14: 50 | E14: 600 | H14: 1200 | L14: 1800 | Q14: =SUM(F14:P14) -> 3000 | R14: =Q14/E14 -> 5 | T14: =HLOOKUP($T$1,$F$1:$P$48,15,FALSE) -> 0 | U14: =$T14/$E14 -> 0
A15: 7 | B15: PP - 1508 | C15: 200 x 15MM Poly Riser. | D15: 10 | E15: 400 | L15: 2000 | M15: 2000 | N15: 1200 | Q15: =SUM(F15:P15) -> 5200 | R15: =Q15/E15 -> 13 | T15: =HLOOKUP($T$1,$F$1:$P$48,16,FALSE) -> 400 | U15: =$T15/$E15 -> 1
A16: 8 | B16: PP - 1509 | C16: 225 x 15MM Poly Riser. | D16: 10 | E16: 400 | G16: 4000 | I16: 8000 | L16: 8000 | M16: 8000 | N16: 7600 | O16: 400 | Q16: =SUM(F16:P16) -> 36000 | R16: =Q16/E16 -> 90 | T16: =HLOOKUP($T$1,$F$1:$P$48,17,FALSE) -> 6000 | U16: =$T16/$E16 -> 15
A17: 9 | B17: PP - 1512 | C17: Risers 1/2"(15MM)x12"(300MM) | D17: 10 | E17: 300 | G17: 6000 | H17: 9000 | I17: 3000 | J17: 12000 | K17: 3000 | N17: 3000 | O17: 6000 | Q17: =SUM(F17:P17) -> 42000 | R17: =Q17/E17 -> 140 | T17: =HLOOKUP($T$1,$F$1:$P$48,18,FALSE) -> 0 | U17: =$T17/$E17 -> 0
A18: 9A | B18: 90441300 | C18: 90441300 P/Riser MXM 15x15x300 | D18: 10 | E18: 300 | H18: 3000 | J18: 3000 | Q18: =SUM(F18:P18) -> 6000 | R18: =Q18/E18 -> 20 | T18: =HLOOKUP($T$1,$F$1:$P$48,19,FALSE) -> 0 | U18: =$T18/$E18 -> 0
A19: 10 | B19: PPA - 1506 | C19: 150 x 15MM Articulated P.Riser. | D19: 10 | E19: 130 | G19: 1300 | H19: 1300 | J19: 1300 | Q19: =SUM(F19:P19) -> 3900 | R19: =Q19/E19 -> 30 | T19: =HLOOKUP($T$1,$F$1:$P$48,21,FALSE) -> 13200 | U19: =$T19/$E19 -> 101.53846
A20: 12 | B20: PPA - 1512 | C20: Articulated Riser 1/2"(15mm)x300MM | D20: 10 | E20: 80 | H20: 800 | J20: 1600 | Q20: =SUM(F20:P20) -> 2400 | R20: =Q20/E20 -> 30 | T20: =HLOOKUP($T$1,$F$1:$P$48,23,FALSE) -> 0 | U20: =$T20/$E20 -> 0
A21: 13 | B21: FFC - 15 | C21: F/F Couplings 1/2"(15MM) | D21: 100 | E21: 1200 | G21: 24000 | H21: 24000 | J21: 25200 | L21: 12000 | M21: 3600 | N21: 7200 | O21: 13200 | Q21: =SUM(F21:P21) -> 109200 | R21: =Q21/E21 -> 91 | T21: =HLOOKUP($T$1,$F$1:$P$48,24,FALSE) -> 0 | U21: =$T21/$E21 -> 0
A22: 14 | B22: MFE - 15 | C22: M/F Elbow 1/2" (15MM) | D22: 100 | E22: 1000 | G22: 5000 | I22: 6000 | J22: 12000 | K22: 5000 | M22: 6000 | N22: 5000 | Q22: =SUM(F22:P22) -> 39000 | R22: =Q22/E22 -> 39 | T22: =HLOOKUP($T$1,$F$1:$P$48,25,FALSE) -> 550 | U22: =$T22/$E22 -> 0.55
A23: 15 | B23: CAP - 15 | C23: 15MM F.I.Cap. | D23: 50 | E23: 2800 | G23: 8400 | I23: 8400 | M23: 5600 | N23: 8400 | Q23: =SUM(F23:P23) -> 30800 | R23: =Q23/E23 -> 11 | T23: =HLOOKUP($T$1,$F$1:$P$48,26,FALSE) -> 2400 | U23: =$T23/$E23 -> 0.85714286
A24: 16 | B24: CUTPL - 15 | C24: 15MM Rigid Cut Off Riser. | D24: 50 | E24: 550 | G24: 5500 | I24: 5500 | M24: 1650 | Q24: =SUM(F24:P24) -> 12650 | R24: =Q24/E24 -> 23 | T24: =HLOOKUP($T$1,$F$1:$P$48,27,FALSE) -> 0 | U24: =$T24/$E24 -> 0
A25: 16A | B25: CUT-15 | C25: 15 MM Flexi Cut-Off Riser | D25: 50 | E25: 550 | G25: 5500 | I25: 1100 | O25: 550 | Q25: =SUM(F25:P25) -> 7150 | R25: =Q25/E25 -> 13 | T25: =HLOOKUP($T$1,$F$1:$P$48,28,FALSE) -> 0 | U25: =$T25/$E25 -> 0
A26: 16B | B26: CUTMF 15 | C26: 15 mm M/F Cut off Riser | D26: 10 | E26: 1200 | M26: 3600 | O26: 2400 | Q26: =SUM(F26:P26) -> 6000 | R26: =Q26/E26 -> 5 | T26: =HLOOKUP($T$1,$F$1:$P$48,29,FALSE) -> 2250 | U26: =$T26/$E26 -> 1.875
A27: 17a | B27: PP 2002 | C27: 50 x 20MM Poly Riser | D27: 10 | E27: 1300 | M27: 1300 | Q27: =SUM(F27:P27) -> 1300 | R27: =Q27/E27 -> 1 | T27: =HLOOKUP($T$1,$F$1:$P$48,31,FALSE) -> 0 | U27: =$T27/$E27 -> 0
A28: 18a | B28: PP 2003 | C28: 80 X 20MM Poly Riser | D28: 10 | E28: 800 | M28: 800 | Q28: =SUM(F28:P28) -> 800 | R28: =Q28/E28 -> 1 | T28: =HLOOKUP($T$1,$F$1:$P$48,33,FALSE) -> 2300 | U28: =$T28/$E28 -> 2.875
B29: PP 2006 | C29: 150 X 20MM Poly Riser | D29: 10 | E29: 450 | G29: 2250 | H29: 2250 | L29: 1800 | O29: 2250 | Q29: =SUM(F29:P29) -> 8550 | R29: =Q29/E29 -> 19 | T29: =HLOOKUP($T$1,$F$1:$P$48,35,FALSE) -> 0 | U29: =$T29/$E29 -> 0
