Workbook

Sheet Sheet1
A1: PACKING LIST
A2: JAIKVIN GLOBAL | E2: Invoice No. | G2: JG/26-27/6002 DT 04.05.2026
A4: Merchant Exporters | E4: Buyers Order No: | G4: JG/26-P/09 DT 27.04.2026
A5: A-101, Rajshree Royale, Navroji Lane, Ghatkopar (W),
A6: MUMBAI-400 086. Maharashtra (State Code : 27) | E6: Other Reference(s):
A7: Tel: 9987122600 E-Mail: aalok.shah@jaikvinglobal.com
A8: On Account & risks of | E8: BL : 'SFPM2605165498 DT. 19.05.2026
A9: Messrs. Corecomp Pty Ltd.,
A10: T/A G.D.Watermark, | E10: Shipped per: CAPE SYROS VOYAGE 092E
A11: 13, Tesla Link,
A12: Wangara WA 6065 (Australia)
E13: Country of Origin | H13: Country of Final Destination
E14: INDIA | H14: AUSTRALIA
E15: Shipping Marks | G15: CONTAINER NO :
A16: Pre-Carraige by: | D16: Place of Receipt by Pre-Carraige | E16: G.D.W. | G16: OOCU0793142
E17: 2001 - 2421 / 2421
A18: Shipped per: | D18: Port of Loading: | G18: SEAL NO :
A19: CAPE SYROS VOYAGE 092E | D19: NHAVA SHEVA-MUMBAI (INDIA) | G19: IND-0054079
A20: Port of Discharge: | D20: Final Destination:
A21: FREMANTLE | D21: FREMANTLE
A22: Sr.Nos. | B22: No. & Kind of Pkgs Description of Goods | G22: Quantity | H22: WEIGHT
B23: 421 PACKAGES (343 CARTONS & 78 HDP BUNDLES) CONTAINING PLASTIC (PP) | H23: NETT | I23: GROSS
B24: EXTRUDED PIPES, PLASTIC (PP) & (PA) MOULDED FITTINGS & CORRUGATED BOXES | H24: KGS | I24: KGS
B25: PLASTIC (PP) EXTRUDED PIPES : BOTH SIDE THREADED PIPES
A26: SR NOS | B26: CODE | C26: SIZE (MM/IN) | D26: LEN (MM) | E26: Qty/Pkg-Pcs | F26: PKGS | G26: PIECES
A27: 2001-2015 | B27: PP1509 | C27: 15 | D27: 225 | E27: 400 | F27: =G27/E27 -> 15 | G27: 6000 | H27: 242.1 | I27: 253
A28: 2016-2051 | B28: PP1518 | C28: 15 | D28: 457 | E28: 200 | F28: =G28/E28 -> 36 | G28: 7200 | H28: 581.04 | I28: 609.51
A29: 2052-2064 | B29: 90441400 | C29: 1/2" | D29: 450 | E29: 200 | F29: =G29/E29 -> 13 | G29: 2600 | H29: 209.82 | I29: 220.35
A30: 2065-2087 | B30: PP1524 | C30: 15 | D30: 610 | E30: 100 | F30: =G30/E30 -> 23 | G30: 2300 | H30: 247.25 | I30: 267.72
A31: 2088-2103 | B31: 90441600 | C31: 1/2" | D31: 600 | E31: 100 | F31: =G31/E31 -> 16 | G31: 1600 | H31: 172 | I31: 186.24
A32: 2104-2113 | B32: PE1536 | C32: 15 | D32: 915 | E32: 100 | F32: =G32/E32 -> 10 | G32: 1000 | H32: 161.4 | I32: 169.5
A33: 2114-2120 | B33: 90441800 | C33: 1/2" | D33: 900 | E33: 100 | F33: =G33/E33 -> 7 | G33: 700 | H33: 112.98 | I33: 118.65
A34: 2121-2121 | B34: PE1548 | C34: 15 | D34: 1220 | E34: 50 | F34: =G34/E34 -> 1 | G34: 50 | H34: 10.75 | I34: 11.64
A35: 2122-2122 | B35: PP2004 | C35: 20 | D35: 100 | E35: 500 | F35: =G35/E35 -> 1 | G35: 500 | H35: 14 | I35: 15.24
A36: 2123-2138 | B36: 90447000 | C36: 3/4" | D36: 240 | E36: 250 | F36: =G36/E36 -> 16 | G36: 4000 | H36: 256 | I36: 276.8
A37: 2139-2142 | B37: PE2018 | C37: 20 | D37: 457 | E37: 100 | F37: =G37/E37 -> 4 | G37: 400 | H37: 52 | I37: 55.2
A38: 2143-2158 | B38: 90442400 | C38: 3/4" | D38: 450 | E38: 100 | F38: =G38/E38 -> 16 | G38: 1600 | H38: 208 | I38: 220.8
A39: 2159-2168 | B39: PE2024 | C39: 20 | D39: 610 | E39: 100 | F39: =G39/E39 -> 10 | G39: 1000 | H39: 170 | I39: 183
A40: 2169-2173 | B40: 90442700 | C40: 3/4" | D40: 750 | E40: 100 | F40: =G40/E40 -> 5 | G40: 500 | H40: 110 | I40: 115
A41: 2174-2177 | B41: PP2508 | C41: 25 | D41: 200 | E41: 150 | F41: =G41/E41 -> 4 | G41: 600 | H41: 43.2 | I41: 46.88
...

Sheet Sheet2
A1: PACKING LIST | H1: Page 2
A2: =Sheet1!A2 -> JAIKVIN GLOBAL | E2: Invoice No. | G2: =Sheet1!G2 -> JG/26-27/6002 DT 04.05.2026
G3: =Sheet1!G3 -> 0
A4: =Sheet1!A4 -> Merchant Exporters | E4: Buyers Order No: | G4: =Sheet1!G4 -> JG/26-P/09 DT 27.04.2026
A5: =Sheet1!A5 -> A-101, Rajshree Royale, Navroji Lane, Ghatkopar (W), | G5: =Sheet1!G5 -> 0
A6: =Sheet1!A6 -> MUMBAI-400 086. Maharashtra (State Code : 27) | E6: Other Reference(s): | G6: =Sheet1!G6 -> 0
A7: =Sheet1!A7 -> Tel: 9987122600 E-Mail: aalok.shah@jaikvinglobal.com | G7: =Sheet1!G7 -> 0
A8: =Sheet1!A8 -> On Account & risks of | D8: =Sheet1!D8 -> 0 | E8: =Sheet1!E8 -> BL : 'SFPM2605165498 DT. 19.05.2026
A9: =Sheet1!A9 -> Messrs. Corecomp Pty Ltd., | E9: =Sheet1!E9 -> 0
A10: =Sheet1!A10 -> T/A G.D.Watermark, | E10: =Sheet1!E10 -> Shipped per: CAPE SYROS VOYAGE 092E
A11: =Sheet1!A11 -> 13, Tesla Link, | E11: =Sheet1!E11 -> 0
A12: =Sheet1!A12 -> Wangara WA 6065 (Australia) | E12: =Sheet1!E12 -> 0
A13: =Sheet1!A13 -> 0 | E13: =Sheet1!E13 -> Country of Origin | H13: =Sheet1!H13 -> Country of Final Destination
A14: =Sheet1!A14 -> 0 | E14: =Sheet1!E14 -> INDIA | H14: =Sheet1!H14 -> AUSTRALIA
A15: =Sheet1!A15 -> 0 | E15: =Sheet1!E15 -> Shipping Marks | G15: =Sheet1!G15 -> CONTAINER NO :
A16: =Sheet1!A16 -> Pre-Carraige by: | D16: =Sheet1!D16 -> Place of Receipt by Pre-Carraige | E16: =Sheet1!E16 -> G.D.W. | G16: =Sheet1!G16 -> OOCU0793142
A17: =Sheet1!A17 | D17: =Sheet1!D17 -> 0 | E17: =Sheet1!E17 -> 2001 - 2421 / 2421 | G17: =Sheet1!G17
A18: =Sheet1!A18 -> Shipped per: | D18: =Sheet1!D18 -> Port of Loading: | E18: =Sheet1!E18 -> 0 | G18: =Sheet1!G18 -> SEAL NO :
A19: =Sheet1!A19 -> CAPE SYROS VOYAGE 092E | D19: =Sheet1!D19 -> NHAVA SHEVA-MUMBAI (INDIA) | E19: =Sheet1!E19 -> 0 | G19: =Sheet1!G19 -> IND-0054079
A20: =Sheet1!A20 -> Port of Discharge: | D20: =Sheet1!D20 -> Final Destination: | E20: =Sheet1!E20 -> 0 | G20: =Sheet1!G20 -> 0
A21: =Sheet1!A21 -> FREMANTLE | D21: =Sheet1!D21 -> FREMANTLE | E21: =Sheet1!E21 -> 0 | G21: =Sheet1!G21 -> 0
A22: Sr.Nos. | B22: No. & Kind of Pkgs Description of Goods | G22: Quantity | H22: WEIGHT
B23: =Sheet1!B23 -> 421 PACKAGES (343 CARTONS & 78 HDP BUNDLES) CONTAINING PLASTIC (PP) | H23: NETT | I23: GROSS
B24: =Sheet1!B24 -> EXTRUDED PIPES, PLASTIC (PP) & (PA) MOULDED FITTINGS & CORRUGATED BOXES | H24: KGS | I24: KGS
B25: PLASTIC (PP) EXTRUDED PIPES : M / F THREADED PIPES | F25: BAL B/F… | H25: =Sheet1!H70 -> 4504.74 | I25: =Sheet1!I70 -> 4781.05
A26: 2285-2286 | B26: PMF2524 | C26: 25 | D26: 600 | E26: 50 | F26: =G26/E26 -> 2 | G26: 100 | H26: 23.5 | I26: 25.24
A27: 2287-2296 | B27: 90445600 | C27: 1" | D27: 600 | E27: 50 | F27: =G27/E27 -> 10 | G27: 500 | H27: 117.5 | I27: 125
A28: 2297-2300 | B28: 90445700 | C28: 1" | D28: 750 | E28: 50 | F28: =G28/E28 -> 4 | G28: 200 | H28: 57.2 | I28: 61.2
A29: 2301-2304 | B29: PMF2536 | C29: 25 | D29: 900 | E29: 50 | F29: =G29/E29 -> 4 | G29: 200 | H29: 68 | I29: 72.8
A30: 2305-2308 | B30: 90445800 | C30: 1" | D30: 900 | E30: 50 | F30: =G30/E30 -> 4 | G30: 200 | H30: 68 | I30: 72.8
B31: PLASTIC (PP) MOULDED FITTINGS
A32: SR NOS | B32: CODE | C32: SIZE (MM) | E32: Qty/Ctn-Pcs | F32: CARTONS | G32: PIECES
A33: 2309-2309 | B33: PET1512 | C33: 15 | E33: 300 | F33: =G33/E33 -> 1 | G33: 300 | H33: 11.5 | I33: 12.5
A34: 2310-2311 | B34: PP1501 / 5 | C34: 15 | E34: 2000 | F34: =G34/E34 -> 2 | G34: 4000 | H34: 17.6 | I34: 19.6
B35: PLASTIC (PA) MOULDED FITTINGS
A36: SR NOS | B36: CODE | C36: SIZE (MM) | E36: Qty/Ctn-Pcs | F36: CARTONS | G36: PIECES
A37: 2312-2315 | B37: GRC15 | C37: 15 | E37: 2500 | F37: =G37/E37 -> 4 | G37: 10000 | H37: 100 | I37: 106
A38: 2316-2317 | B38: GRC20 | C38: 20 | E38: 1500 | F38: =G38/E38 -> 2 | G38: 3000 | H38: 36 | I38: 39.4
A39: 2318-2318 | B39: GRC25 | C39: 25 | E39: 900 | F39: =G39/E39 -> 1 | G39: 900 | H39: 16.7 | I39: 18
A40: 2319-2322 | B40: GRMFE25 | C40: 25 | E40: 350 | F40: =G40/E40 -> 4 | G40: 1400 | H40: 51.6 | I40: 56
...
